Workbook
Name PhaseID_List: 'Lists'!$A$2:$A$101
Name PhaseName_List: 'Lists'!$B$2:$B$101
Name BedroomType_List: 'Lists'!$C$2:$C$8
Name RentBasis_List: 'Lists'!$D$2:$D$6
Name UseType_List: 'Lists'!$E$2:$E$4
Name RentType_List: 'Lists'!$F$2:$F$3
Name CostCurve_List: 'Lists'!$G$2:$G$5
Name YesNo_List: 'Lists'!$H$2:$H$3
Name AMI_4person: 'Master Assumptions'!$B$5
Name FMR_Table: 'Master Assumptions'!$B$9:$B$15
Name UtilAllow_Table: 'Master Assumptions'!$C$9:$C$15
Name HHSizeFactor_Table: 'Master Assumptions'!$D$9:$D$15
Name Bedroom_Index: 'Master Assumptions'!$A$9:$A$15
Name Basis_Index: 'Master Assumptions'!$A$18:$A$22
Name Tier_Table: 'Master Assumptions'!$B$18:$B$22
Name FMRFactor_Table: 'Master Assumptions'!$C$18:$C$22
Name DerivRent_Matrix: 'Master Assumptions'!$B$26:$E$32
Name DerivRent_Beds: 'Master Assumptions'!$A$26:$A$32
Name DerivRent_Bases: 'Master Assumptions'!$B$25:$E$25
Name Growth_Defaults: 'Master Assumptions'!$B$39:$F$43
Name Growth_Rows: 'Master Assumptions'!$A$39:$A$43
Name SelectedPhase: 'Cockpit'!$B$4
Name Cockpit_Notes: 'Cockpit'!$B$5
Name Closing_Date_Cell: 'Cockpit'!$B$24
Name LeaseUpPace_in: 'Cockpit'!$B$32
Name UM_Units: 'Cockpit'!$C$37:$C$51
Name UM_TotSF: 'Cockpit'!$G$37:$G$51
Name UM_TotRent: 'Cockpit'!$J$37:$J$51
Name UM_Basis: 'Cockpit'!$B$37:$B$51
Name Units_Total: 'Cockpit'!$C$52
Name ResSF_Total: 'Cockpit'!$G$52
Name ResRent_Total_mo: 'Cockpit'!$J$52
Name OpEx_Total: 'Cockpit'!$D$91
Name Comm_NOI: 'Cockpit'!$B$124
Name TotalDevCost: 'Cockpit'!$B$151
Name GPR_Annual: 'Cockpit'!$C$153
Name LossOldLease: 'Cockpit'!$C$154
Name NetRentRev: 'Cockpit'!$C$155
Name VacancyAmt: 'Cockpit'!$C$156
Name ConcessionAmt: 'Cockpit'!$C$157
Name CollLoss: 'Cockpit'!$C$158
Name EffRentRev: 'Cockpit'!$C$159
Name OtherIncomeNet: 'Cockpit'!$C$160
Name EGI_Annual: 'Cockpit'!$C$161
Name TotOpEx: 'Cockpit'!$C$170
Name OpExRatio: 'Cockpit'!$C$171
Name NOI_Res: 'Cockpit'!$C$172
Name NOI_CommLine: 'Cockpit'!$C$173
Name NOI_Total: 'Cockpit'!$C$174
Name HasCommercial_ref: 'Cockpit'!$B$16
Name MaxRecordsPerPhase: 'Database'!$B$2
Name SelectedPhaseDetail: 'Phase Detail'!$B$3
Name CF_Closing: 'Monthly CF'!$B$4

Sheet Read me
A1: Swerdlow Multi-Phase Cockpit Model
A3: WHAT THIS IS
A4: Scalable input template / 'cockpit' for a multi-phase real estate development program. This pass builds the input + assumptions architecture and a single stabilized (untrended) proforma summary. No monthly CF engine, financing, or equity waterfall (explicitly out of scope, designed so they can be added later).
A6: TABS (left to right)
A7: Read me | Cockpit | Master Assumptions | Database | All Phases | Phase Detail | Monthly CF. Hidden support: Lists, Archive.
A9: OPERATING LOOP
A10: USER edits inputs on the COCKPIT (one Phase at a time) -> clicks UPDATE -> a flat snapshot row is appended to the DATABASE (system of record). All Phases / Phase Detail / Monthly CF read the latest record per phase from the Database.
A12: COLOR CODING
A13: Blue font + light-blue fill = [INPUT] (you type here). Black = [CALC] formula. Green = [LINK] cross-tab reference.
A15: ** ENABLING THE MACROS (.xlsx -> .xlsm) **
A16: Pure-Python tooling cannot author Excel's compiled VBA project, so the 3 macros ship as importable text modules in the ./vba folder (UPDATE_Phase, Add_Asset, Request_Support / Validate_Inputs). To enable them:
A17: 1. Open this .xlsx in Excel. File > Save As > Excel Macro-Enabled Workbook (.xlsm).
... A26: All Phases and Phase Detail use the MAXIFS+INDEX 'latest record per phase' pattern. Because the Database stores raw inputs (not the computed EGI/NOI), the program-level $ roll-ups recompute from those inputs; the full recompute formulas land alongside the monthly CF engine in the next pass. Cells showing '-' are intentional placeholders, labeled here rather than silently faked.

Sheet Cockpit
A1: COCKPIT - single editable surface (one Phase at a time)
A2: Edit blue cells, then click UPDATE to save a snapshot to the Database.
A4: Selected Phase | B4: 1-2A | D4: Last updated by | E4: =IFERROR(INDEX(Database!$E:$E,MATCH(MAXIFS(Database!$A:$A,Database!$B:$B,SelectedPhase),Database!$A:$A,0)),"(none)") | F4: on | G4: =IFERROR(INDEX(Database!$D:$D,MATCH(MAXIFS(Database!$A:$A,Database!$B:$B,SelectedPhase),Database!$A:$A,0)),"(none)") | H4: Record # | I4: =IFERROR(MAXIFS(Database!$A:$A,Database!$B:$B,SelectedPhase),0)
A5: Notes (saved with next UPDATE) | G5: UPDATE | I5: Add Asset | K5: Request Support
A6: Buttons above are placeholders; assign macros after importing the .bas modules (see README).
A8: KPI strip (computed from current Cockpit inputs)
A9: Total Units | B9: Total Res NSF | C9: EGI | D9: NOI | E9: OpEx Ratio | F9: NOI / Unit | G9: Total Dev Cost | H9: Cost / Unit | I9: Cost / GSF
A10: =Units_Total | B10: =ResSF_Total | C10: =EGI_Annual | D10: =NOI_Total | E10: =OpExRatio | F10: =IFERROR(NOI_Total/Units_Total,0) | G10: =TotalDevCost | H10: =IFERROR(TotalDevCost/Units_Total,0) | I10: =IFERROR(TotalDevCost/N(B18),0)
C11: Saved value
A12: (1) Phase Identity & Physical
A13: Phase Name | B13: Site 1 - Bldg 2A | C13: =IFERROR(INDEX(Database!$G:$G,MATCH(MAXIFS(Database!$A:$A,Database!$B:$B,SelectedPhase),Database!$A:$A,0)),"-") | D13: =IF(B13="","<-- needs input","")
A14: Site | B14: Site 1 | C14: =IFERROR(INDEX(Database!$H:$H,MATCH(MAXIFS(Database!$A:$A,Database!$B:$B,SelectedPhase),Database!$A:$A,0)),"-") | D14: =IF(B14="","<-- needs input","")
A15: Has Residential? | B15: Yes | C15: =IFERROR(INDEX(Database!$I:$I,MATCH(MAXIFS(Database!$A:$A,Database!$B:$B,SelectedPhase),Database!$A:$A,0)),"-")
A16: Has Commercial? | B16: No | C16: =IFERROR(INDEX(Database!$J:$J,MATCH(MAXIFS(Database!$A:$A,Database!$B:$B,SelectedPhase),Database!$A:$A,0)),"-")
A17: Stories | B17: 8 | C17: =IFERROR(INDEX(Database!$K:$K,MATCH(MAXIFS(Database!$A:$A,Database!$B:$B,SelectedPhase),Database!$A:$A,0)),"-")
A18: Gross Building Area (GSF) | B18: 240000 | C18: =IFERROR(INDEX(Database!$L:$L,MATCH(MAXIFS(Database!$A:$A,Database!$B:$B,SelectedPhase),Database!$A:$A,0)),"-") | D18: =IF(N(B18)=0,"<-- needs input","")
A19: Net Rentable Area (NSF) | B19: 200000 | C19: =IFERROR(INDEX(Database!$M:$M,MATCH(MAXIFS(Database!$A:$A,Database!$B:$B,SelectedPhase),Database!$A:$A,0)),"-")
A20: Parking spaces | B20: 250 | C20: =IFERROR(INDEX(Database!$N:$N,MATCH(MAXIFS(Database!$A:$A,Database!$B:$B,SelectedPhase),Database!$A:$A,0)),"-")
A21: Land area (SF) | B21: 60000 | C21: =IFERROR(INDEX(Database!$O:$O,MATCH(MAXIFS(Database!$A:$A,Database!$B:$B,SelectedPhase),Database!$A:$A,0)),"-")
A22: Parking ratio (per unit) | B22: =IFERROR(B20/Units_Total,0)
A23: (2) Key Dates & Lease-Up (Exhibit F)
A24: Closing date | B24: 46023 | C24: =IFERROR(INDEX(Database!$P:$P,MATCH(MAXIFS(Database!$A:$A,Database!$B:$B,SelectedPhase),Database!$A:$A,0)),"-") | D24: =IF(B24="","<-- needs input","")
A25: Construction Start (month offset) | B25: 2 | C25: =EDATE(B24,B25) | D25: abs. date
A26: Initial Occupancy (month offset) | B26: 14 | C26: =EDATE(B24,B26) | D26: abs. date
A27: Construction End (month offset) | B27: 20 | C27: =EDATE(B24,B27) | D27: abs. date
A28: Stabilization (month offset) | B28: 30 | C28: =EDATE(B24,B28) | D28: abs. date
A29: Exit (month offset) | B29: 84 | C29: =EDATE(B24,B29) | D29: abs. date
A30: Preleased units | B30: 20 | C30: =IFERROR(INDEX(Database!$V:$V,MATCH(MAXIFS(Database!$A:$A,Database!$B:$B,SelectedPhase),Database!$A:$A,0)),"-")
A31: Preleased % | B31: =IFERROR(B30/Units_Total,0)
A32: Lease-up pace (units/month) | B32: 15 | C32: =IFERROR(INDEX(Database!$W:$W,MATCH(MAXIFS(Database!$A:$A,Database!$B:$B,SelectedPhase),Database!$A:$A,0)),"-")
A33: Initial delivery units | B33: 60 | C33: =IFERROR(INDEX(Database!$X:$X,MATCH(MAXIFS(Database!$A:$A,Database!$B:$B,SelectedPhase),Database!$A:$A,0)),"-")
A34: Duration of lease-up to stabilization (mo) | B34: =IFERROR(MAX(0,(Units_Total-B30)/MAX(LeaseUpPace_in,1)),0)
A35: (3) Residential Unit Mix (Exhibit A) - 15 rows
A36: Bedroom Type | B36: Rent Basis | C36: Units | D36: Avg SF | E36: Mkt Rent override | F36: Rent/unit/mo | G36: Total SF | H36: % Units | I36: % of Tot SF | J36: Total Rent/mo | K36: Rent PSF
A37: Studio | B37: Market | C37: 10 | D37: 520 | E37: 2100 | F37: =IFERROR(IF($C37="",0,IF($B37="Market",$E37,INDEX(DerivRent_Matrix,MATCH($A37,DerivRent_Beds,0),MATCH($B37,DerivRent_Bases,0)))),0) | G37: =N($C37)*N($D37) | H37: =IFERROR($C37/Units_Total,0) | I37: =IFERROR($G37/ResSF_Total,0) | J37: =N($C37)*N($F37) | K37: =IFERROR($J37/$C37/$D37,0)
F38: =IFERROR(IF($C38="",0,IF($B38="Market",$E38,INDEX(DerivRent_Matrix,MATCH($A38,DerivRent_Beds,0),MATCH($B38,DerivRent_Bases,0)))),0) | G38: =N($C38)*N($D38) | H38: =IFERROR($C38/Units_Total,0) | I38: =IFERROR($G38/ResSF_Total,0) | J38: =N($C38)*N($F38) | K38: =IFERROR($J38/$C38/$D38,0)
F39: =IFERROR(IF($C39="",0,IF($B39="Market",$E39,INDEX(DerivRent_Matrix,MATCH($A39,DerivRent_Beds,0),MATCH($B39,DerivRent_Bases,0)))),0) | G39: =N($C39)*N($D39) | H39: =IFERROR($C39/Units_Total,0) | I39: =IFERROR($G39/ResSF_Total,0) | J39: =N($C39)*N($F39) | K39: =IFERROR($J39/$C39/$D39,0)
F40: =IFERROR(IF($C40="",0,IF($B40="Market",$E40,INDEX(DerivRent_Matrix,MATCH($A40,DerivRent_Beds,0),MATCH($B40,DerivRent_Bases,0)))),0) | G40: =N($C40)*N($D40) | H40: =IFERROR($C40/Units_Total,0) | I40: =IFERROR($G40/ResSF_Total,0) | J40: =N($C40)*N($F40) | K40: =IFERROR($J40/$C40/$D40,0)
F41: =IFERROR(IF($C41="",0,IF($B41="Market",$E41,INDEX(DerivRent_Matrix,MATCH($A41,DerivRent_Beds,0),MATCH($B41,DerivRent_Bases,0)))),0) | G41: =N($C41)*N($D41) | H41: =IFERROR($C41/Units_Total,0) | I41: =IFERROR($G41/ResSF_Total,0) | J41: =N($C41)*N($F41) | K41: =IFERROR($J41/$C41/$D41,0)
F42: =IFERROR(IF($C42="",0,IF($B42="Market",$E42,INDEX(DerivRent_Matrix,MATCH($A42,DerivRent_Beds,0),MATCH($B42,DerivRent_Bases,0)))),0) | G42: =N($C42)*N($D42) | H42: =IFERROR($C42/Units_Total,0) | I42: =IFERROR($G42/ResSF_Total,0) | J42: =N($C42)*N($F42) | K42: =IFERROR($J42/$C42/$D42,0)
...

Sheet Master Assumptions
A1: MASTER ASSUMPTIONS - program-wide drivers
A2: Program-wide drivers feed the Cockpit Rent Basis Engine. Blue = input.
A4: 4.1a Rent Basis Engine inputs
A5: AMI (4-person household, annual) | B5: 110000
A7: Per-bedroom table
A8: Bedroom | B8: FMR (mo) | C8: UtilAllow (mo) | D8: HHSizeFactor
A9: Studio | B9: 1400 | C9: 85 | D9: 0.7
A10: 1BR | B10: 1550 | C10: 110 | D10: 0.75
A11: 1BR+Den | B11: 1650 | C11: 120 | D11: 0.75
A12: 2BR | B12: 1850 | C12: 150 | D12: 0.9
A13: 2BR+Den | B13: 1975 | C13: 160 | D13: 0.9
A14: 3BR | B14: 2350 | C14: 195 | D14: 1.04
A15: 3BR+Den | B15: 2500 | C15: 210 | D15: 1.04
A16: Basis factor table
A17: Basis | B17: Tier % | C17: FMR_Factor
A18: Market
A19: Live Local | B19: 0.8
A20: LIHTC | B20: 0.6
A21: PBV | C21: 1.1
A22: RAD | C22: 1.05
A24: 4.1b Derived net rent / unit / month (by bedroom x basis)
A25: Bedroom | B25: Live Local | C25: LIHTC | D25: PBV | E25: RAD
A26: Studio | B26: =MAX(0, AMI_4person*INDEX(HHSizeFactor_Table,MATCH($A26,Bedroom_Index,0))*INDEX(Tier_Table,MATCH("Live Local",Basis_Index,0))*0.3/12 - INDEX(UtilAllow_Table,MATCH($A26,Bedroom_Index,0))) | C26: =MAX(0, AMI_4person*INDEX(HHSizeFactor_Table,MATCH($A26,Bedroom_Index,0))*INDEX(Tier_Table,MATCH("LIHTC",Basis_Index,0))*0.3/12 - INDEX(UtilAllow_Table,MATCH($A26,Bedroom_Index,0))) | D26: =MAX(0, INDEX(FMR_Table,MATCH($A26,Bedroom_Index,0))*INDEX(FMRFactor_Table,MATCH("PBV",Basis_Index,0)) - INDEX(UtilAllow_Table,MATCH($A26,Bedroom_Index,0))) | E26: =MAX(0, INDEX(FMR_Table,MATCH($A26,Bedroom_Index,0))*INDEX(FMRFactor_Table,MATCH("RAD",Basis_Index,0)) - INDEX(UtilAllow_Table,MATCH($A26,Bedroom_Index,0)))
A27: 1BR | B27: =MAX(0, AMI_4person*INDEX(HHSizeFactor_Table,MATCH($A27,Bedroom_Index,0))*INDEX(Tier_Table,MATCH("Live Local",Basis_Index,0))*0.3/12 - INDEX(UtilAllow_Table,MATCH($A27,Bedroom_Index,0))) | C27: =MAX(0, AMI_4person*INDEX(HHSizeFactor_Table,MATCH($A27,Bedroom_Index,0))*INDEX(Tier_Table,MATCH("LIHTC",Basis_Index,0))*0.3/12 - INDEX(UtilAllow_Table,MATCH($A27,Bedroom_Index,0))) | D27: =MAX(0, INDEX(FMR_Table,MATCH($A27,Bedroom_Index,0))*INDEX(FMRFactor_Table,MATCH("PBV",Basis_Index,0)) - INDEX(UtilAllow_Table,MATCH($A27,Bedroom_Index,0))) | E27: =MAX(0, INDEX(FMR_Table,MATCH($A27,Bedroom_Index,0))*INDEX(FMRFactor_Table,MATCH("RAD",Basis_Index,0)) - INDEX(UtilAllow_Table,MATCH($A27,Bedroom_Index,0)))
A28: 1BR+Den | B28: =MAX(0, AMI_4person*INDEX(HHSizeFactor_Table,MATCH($A28,Bedroom_Index,0))*INDEX(Tier_Table,MATCH("Live Local",Basis_Index,0))*0.3/12 - INDEX(UtilAllow_Table,MATCH($A28,Bedroom_Index,0))) | C28: =MAX(0, AMI_4person*INDEX(HHSizeFactor_Table,MATCH($A28,Bedroom_Index,0))*INDEX(Tier_Table,MATCH("LIHTC",Basis_Index,0))*0.3/12 - INDEX(UtilAllow_Table,MATCH($A28,Bedroom_Index,0))) | D28: =MAX(0, INDEX(FMR_Table,MATCH($A28,Bedroom_Index,0))*INDEX(FMRFactor_Table,MATCH("PBV",Basis_Index,0)) - INDEX(UtilAllow_Table,MATCH($A28,Bedroom_Index,0))) | E28: =MAX(0, INDEX(FMR_Table,MATCH($A28,Bedroom_Index,0))*INDEX(FMRFactor_Table,MATCH("RAD",Basis_Index,0)) - INDEX(UtilAllow_Table,MATCH($A28,Bedroom_Index,0)))
A29: 2BR | B29: =MAX(0, AMI_4person*INDEX(HHSizeFactor_Table,MATCH($A29,Bedroom_Index,0))*INDEX(Tier_Table,MATCH("Live Local",Basis_Index,0))*0.3/12 - INDEX(UtilAllow_Table,MATCH($A29,Bedroom_Index,0))) | C29: =MAX(0, AMI_4person*INDEX(HHSizeFactor_Table,MATCH($A29,Bedroom_Index,0))*INDEX(Tier_Table,MATCH("LIHTC",Basis_Index,0))*0.3/12 - INDEX(UtilAllow_Table,MATCH($A29,Bedroom_Index,0))) | D29: =MAX(0, INDEX(FMR_Table,MATCH($A29,Bedroom_Index,0))*INDEX(FMRFactor_Table,MATCH("PBV",Basis_Index,0)) - INDEX(UtilAllow_Table,MATCH($A29,Bedroom_Index,0))) | E29: =MAX(0, INDEX(FMR_Table,MATCH($A29,Bedroom_Index,0))*INDEX(FMRFactor_Table,MATCH("RAD",Basis_Index,0)) - INDEX(UtilAllow_Table,MATCH($A29,Bedroom_Index,0)))
A30: 2BR+Den | B30: =MAX(0, AMI_4person*INDEX(HHSizeFactor_Table,MATCH($A30,Bedroom_Index,0))*INDEX(Tier_Table,MATCH("Live Local",Basis_Index,0))*0.3/12 - INDEX(UtilAllow_Table,MATCH($A30,Bedroom_Index,0))) | C30: =MAX(0, AMI_4person*INDEX(HHSizeFactor_Table,MATCH($A30,Bedroom_Index,0))*INDEX(Tier_Table,MATCH("LIHTC",Basis_Index,0))*0.3/12 - INDEX(UtilAllow_Table,MATCH($A30,Bedroom_Index,0))) | D30: =MAX(0, INDEX(FMR_Table,MATCH($A30,Bedroom_Index,0))*INDEX(FMRFactor_Table,MATCH("PBV",Basis_Index,0)) - INDEX(UtilAllow_Table,MATCH($A30,Bedroom_Index,0))) | E30: =MAX(0, INDEX(FMR_Table,MATCH($A30,Bedroom_Index,0))*INDEX(FMRFactor_Table,MATCH("RAD",Basis_Index,0)) - INDEX(UtilAllow_Table,MATCH($A30,Bedroom_Index,0)))
A31: 3BR | B31: =MAX(0, AMI_4person*INDEX(HHSizeFactor_Table,MATCH($A31,Bedroom_Index,0))*INDEX(Tier_Table,MATCH("Live Local",Basis_Index,0))*0.3/12 - INDEX(UtilAllow_Table,MATCH($A31,Bedroom_Index,0))) | C31: =MAX(0, AMI_4person*INDEX(HHSizeFactor_Table,MATCH($A31,Bedroom_Index,0))*INDEX(Tier_Table,MATCH("LIHTC",Basis_Index,0))*0.3/12 - INDEX(UtilAllow_Table,MATCH($A31,Bedroom_Index,0))) | D31: =MAX(0, INDEX(FMR_Table,MATCH($A31,Bedroom_Index,0))*INDEX(FMRFactor_Table,MATCH("PBV",Basis_Index,0)) - INDEX(UtilAllow_Table,MATCH($A31,Bedroom_Index,0))) | E31: =MAX(0, INDEX(FMR_Table,MATCH($A31,Bedroom_Index,0))*INDEX(FMRFactor_Table,MATCH("RAD",Basis_Index,0)) - INDEX(UtilAllow_Table,MATCH($A31,Bedroom_Index,0)))
A32: 3BR+Den | B32: =MAX(0, AMI_4person*INDEX(HHSizeFactor_Table,MATCH($A32,Bedroom_Index,0))*INDEX(Tier_Table,MATCH("Live Local",Basis_Index,0))*0.3/12 - INDEX(UtilAllow_Table,MATCH($A32,Bedroom_Index,0))) | C32: =MAX(0, AMI_4person*INDEX(HHSizeFactor_Table,MATCH($A32,Bedroom_Index,0))*INDEX(Tier_Table,MATCH("LIHTC",Basis_Index,0))*0.3/12 - INDEX(UtilAllow_Table,MATCH($A32,Bedroom_Index,0))) | D32: =MAX(0, INDEX(FMR_Table,MATCH($A32,Bedroom_Index,0))*INDEX(FMRFactor_Table,MATCH("PBV",Basis_Index,0)) - INDEX(UtilAllow_Table,MATCH($A32,Bedroom_Index,0))) | E32: =MAX(0, INDEX(FMR_Table,MATCH($A32,Bedroom_Index,0))*INDEX(FMRFactor_Table,MATCH("RAD",Basis_Index,0)) - INDEX(UtilAllow_Table,MATCH($A32,Bedroom_Index,0)))
A34: Note: LIHTC / Live Local rents are AMI-based; PBV and RAD are HUD-FMR-based; Market is entered directly on the Cockpit.
A35: Changing AMI or FMR re-solves every affordable rent across all phases automatically.
A37: 4.1c Growth-rate defaults (Exhibit E)
A38: Category | B38: Year 1 | C38: Year 2 | D38: Year 3 | E38: Year 4 | F38: Year 5 | G38: Yr5 = Yr5+
A39: Market Rents | B39: 0.03 | C39: 0.03 | D39: 0.03 | E39: 0.03 | F39: 0.03
A40: Affordable Rents | B40: 0.025 | C40: 0.025 | D40: 0.025 | E40: 0.025 | F40: 0.025
A41: Retail Rents | B41: 0.025 | C41: 0.025 | D41: 0.025 | E41: 0.025 | F41: 0.025
A42: Other Income | B42: 0.025 | C42: 0.025 | D42: 0.025 | E42: 0.025 | F42: 0.025
A43: Operating Expenses | B43: 0.03 | C43: 0.03 | D43: 0.03 | E43: 0.03 | F43: 0.03

Sheet Database
A1: DATABASE - system of record (flat snapshot ledger). One row = one saved Record for one Phase. Do not edit by hand.
A2: MaxRecordsPerPhase | B2: 20 | C2: FIFO cap; on exceed, oldest record for that Phase is moved to Archive (see VBA). Trade-off: archive (recoverable) vs hard-delete.
A4: RecordID | B4: PhaseID | C4: PhaseName | D4: Timestamp | E4: UpdatedBy | F4: Notes | G4: PhaseName_in | H4: Site_in | I4: HasResidential | J4: HasCommercial | K4: Stories | L4: GSF | M4: NetRentableArea | N4: ParkingSpaces | O4: LandArea | P4: ClosingDate | Q4: off_ConstStart | R4: off_InitialOcc | S4: off_ConstEnd | T4: off_Stab | U4: off_Exit | V4: PreleasedUnits | W4: LeaseUpPace | X4: InitialDeliveryUnits | Y4: UM01_Bed | Z4: UM01_Basis | AA4: UM01_Units | AB4: UM01_AvgSF | AC4: UM01_MktOvr | AD4: UM02_Bed | AE4: UM02_Basis | AF4: UM02_Units | AG4: UM02_AvgSF | AH4: UM02_MktOvr | AI4: UM03_Bed | AJ4: UM03_Basis | AK4: UM03_Units | AL4: UM03_AvgSF | AM4: UM03_MktOvr | AN4: UM04_Bed | AO4: UM04_Basis | AP4: UM04_Units | AQ4: UM04_AvgSF | AR4: UM04_MktOvr | AS4: UM05_Bed | AT4: UM05_Basis | AU4: UM05_Units | AV4: UM05_AvgSF | AW4: UM05_MktOvr | AX4: UM06_Bed | AY4: UM06_Basis | AZ4: UM06_Units | BA4: UM06_AvgSF | BB4: UM06_MktOvr | BC4: UM07_Bed | BD4: UM07_Basis | BE4: UM07_Units | BF4: UM07_AvgSF | BG4: UM07_MktOvr | BH4: UM08_Bed | BI4: UM08_Basis | BJ4: UM08_Units | BK4: UM08_AvgSF | BL4: UM08_MktOvr | BM4: UM09_Bed | BN4: UM09_Basis | BO4: UM09_Units | BP4: UM09_AvgSF | BQ4: UM09_MktOvr | BR4: UM10_Bed | BS4: UM10_Basis | BT4: UM10_Units | BU4: UM10_AvgSF | BV4: UM10_MktOvr | BW4: UM11_Bed | BX4: UM11_Basis | BY4: UM11_Units | BZ4: UM11_AvgSF | CA4: UM11_MktOvr | CB4: UM12_Bed | CC4: UM12_Basis | CD4: UM12_Units | CE4: UM12_AvgSF | CF4: UM12_MktOvr | CG4: UM13_Bed | CH4: UM13_Basis | CI4: UM13_Units | CJ4: UM13_AvgSF | CK4: UM13_MktOvr | CL4: UM14_Bed | CM4: UM14_Basis | CN4: UM14_Units | CO4: UM14_AvgSF | CP4: UM14_MktOvr | CQ4: UM15_Bed | CR4: UM15_Basis | CS4: UM15_Units | CT4: UM15_AvgSF | CU4: UM15_MktOvr | CV4: TurnoverRate | CW4: VacancyLossPct | CX4: CollectionLossPct | CY4: ModelUnits | CZ4: NonRevenueUnits | DA4: NonRevDiscountPct | DB4: LUConcMonths | DC4: LUConcPctLeases | DD4: StabConcMonths | DE4: StabConcPctLeases | DF4: OtherIncome_Cnt | DG4: OtherIncome_Capture | DH4: OtherIncome_Rate | DI4: ParkingRev_Cnt | DJ4: ParkingRev_Capture | DK4: ParkingRev_Rate | DL4: StorageRev_Cnt | DM4: StorageRev_Capture | DN4: StorageRev_Rate | DO4: RUBS_Cnt | DP4: RUBS_Capture | DQ4: RUBS_Rate | DR4: MgmtFeePct | DS4: Payroll_FixedPct | DT4: Payroll_PerUnit | DU4: Marketing_FixedPct | DV4: Marketing_PerUnit | DW4: RM_FixedPct | DX4: RM_PerUnit | DY4: Turnover_FixedPct | DZ4: Turnover_PerUnit | EA4: GA_FixedPct | EB4: GA_PerUnit | EC4: ContractSvcs_FixedPct | ED4: ContractSvcs_PerUnit | EE4: Utilities_FixedPct | EF4: Utilities_PerUnit | EG4: Insurance_FixedPct | EH4: Insurance_PerUnit | EI4: ReplReserve_FixedPct | EJ4: ReplReserve_PerUnit | EK4: RETax_Market | EL4: RETax_Afford | EM4: Comm_TotalSF | EN4: Comm_StaticPct | EO4: Comm_GenVac | EP4: Comm_VarPct | EQ4: Comm_VarPSF | ER4: Comm_InsPSF | ES4: Comm_TaxPSF | ET4: Comm_MgmtPct | EU4: RR01_Name | EV4: RR01_SF | EW4: RR01_StartMo | EX4: RR01_LCD | EY4: RR01_Term | EZ4: RR01_RentPSF | FA4: RR01_RentType | FB4: RR01_Escal | FC4: RR01_TIPSF | FD4: RR01_LCPct | FE4: RR01_FreeRentMo | FF4: RR01_FreeStart | FG4: RR01_Abatement | FH4: RR02_Name | FI4: RR02_SF | FJ4: RR02_StartMo | FK4: RR02_LCD | FL4: RR02_Term | FM4: RR02_RentPSF | FN4: RR02_RentType | FO4: RR02_Escal | FP4: RR02_TIPSF | FQ4: RR02_LCPct | FR4: RR02_FreeRentMo | FS4: RR02_FreeStart | FT4: RR02_Abatement | FU4: RR03_Name | FV4: RR03_SF | FW4: RR03_StartMo | FX4: RR03_LCD | FY4: RR03_Term | FZ4: RR03_RentPSF | GA4: RR03_RentType | GB4: RR03_Escal | GC4: RR03_TIPSF | GD4: RR03_LCPct | GE4: RR03_FreeRentMo | GF4: RR03_FreeStart | GG4: RR03_Abatement | GH4: RR04_Name | GI4: RR04_SF | GJ4: RR04_StartMo | GK4: RR04_LCD | GL4: RR04_Term | GM4: RR04_RentPSF | GN4: RR04_RentType | GO4: RR04_Escal | GP4: RR04_TIPSF | GQ4: RR04_LCPct | GR4: RR04_FreeRentMo | GS4: RR04_FreeStart | GT4: RR04_Abatement | GU4: RR05_Name | GV4: RR05_SF | GW4: RR05_StartMo | GX4: RR05_LCD | GY4: RR05_Term | GZ4: RR05_RentPSF | HA4: RR05_RentType | HB4: RR05_Escal | HC4: RR05_TIPSF | HD4: RR05_LCPct | HE4: RR05_FreeRentMo | HF4: RR05_FreeStart | HG4: RR05_Abatement | HH4: RR06_Name | HI4: RR06_SF | HJ4: RR06_StartMo | HK4: RR06_LCD | HL4: RR06_Term | HM4: RR06_RentPSF | HN4: RR06_RentType | HO4: RR06_Escal | HP4: RR06_TIPSF | HQ4: RR06_LCPct | HR4: RR06_FreeRentMo | HS4: RR06_FreeStart | HT4: RR06_Abatement | HU4: RR07_Name | HV4: RR07_SF | HW4: RR07_StartMo | HX4: RR07_LCD | HY4: RR07_Term | HZ4: RR07_RentPSF | IA4: RR07_RentType | IB4: RR07_Escal | IC4: RR07_TIPSF | ID4: RR07_LCPct | IE4: RR07_FreeRentMo | IF4: RR07_FreeStart | IG4: RR07_Abatement | IH4: RR08_Name | II4: RR08_SF | IJ4: RR08_StartMo | IK4: RR08_LCD | IL4: RR08_Term | IM4: RR08_RentPSF | IN4: RR08_RentType | IO4: RR08_Escal | IP4: RR08_TIPSF | IQ4: RR08_LCPct | IR4: RR08_FreeRentMo | IS4: RR08_FreeStart | IT4: RR08_Abatement | IU4: RR09_Name | IV4: RR09_SF | IW4: RR09_StartMo | IX4: RR09_LCD | IY4: RR09_Term | IZ4: RR09_RentPSF | JA4: RR09_RentType | JB4: RR09_Escal | JC4: RR09_TIPSF | JD4: RR09_LCPct | JE4: RR09_FreeRentMo | JF4: RR09_FreeStart | JG4: RR09_Abatement | JH4: RR10_Name | JI4: RR10_SF | JJ4: RR10_StartMo | JK4: RR10_LCD | JL4: RR10_Term | JM4: RR10_RentPSF | JN4: RR10_RentType | JO4: RR10_Escal | JP4: RR10_TIPSF | JQ4: RR10_LCPct | JR4: RR10_FreeRentMo | JS4: RR10_FreeStart | JT4: RR10_Abatement | JU4: RR11_Name | JV4: RR11_SF | JW4: RR11_StartMo | JX4: RR11_LCD | JY4: RR11_Term | JZ4: RR11_RentPSF | KA4: RR11_RentType | KB4: RR11_Escal | KC4: RR11_TIPSF | KD4: RR11_LCPct | KE4: RR11_FreeRentMo | KF4: RR11_FreeStart | KG4: RR11_Abatement | KH4: RR12_Name | KI4: RR12_SF | KJ4: RR12_StartMo | KK4: RR12_LCD | KL4: RR12_Term | KM4: RR12_RentPSF | KN4: RR12_RentType | KO4: RR12_Escal | KP4: RR12_TIPSF | KQ4: RR12_LCPct | KR4: RR12_FreeRentMo | KS4: RR12_FreeStart | KT4: RR12_Abatement | KU4: RR13_Name | KV4: RR13_SF | KW4: RR13_StartMo | KX4: RR13_LCD | KY4: RR13_Term | KZ4: RR13_RentPSF | LA4: RR13_RentType | LB4: RR13_Escal | LC4: RR13_TIPSF | LD4: RR13_LCPct | LE4: RR13_FreeRentMo | LF4: RR13_FreeStart | LG4: RR13_Abatement | LH4: RR14_Name | LI4: RR14_SF | LJ4: RR14_StartMo | LK4: RR14_LCD | LL4: RR14_Term | LM4: RR14_RentPSF | LN4: RR14_RentType | LO4: RR14_Escal | LP4: RR14_TIPSF | LQ4: RR14_LCPct | LR4: RR14_FreeRentMo | LS4: RR14_FreeStart | LT4: RR14_Abatement | LU4: RR15_Name | LV4: RR15_SF | LW4: RR15_StartMo | LX4: RR15_LCD | LY4: RR15_Term | LZ4: RR15_RentPSF | MA4: RR15_RentType | MB4: RR15_Escal | MC4: RR15_TIPSF | MD4: RR15_LCPct | ME4: RR15_FreeRentMo | MF4: RR15_FreeStart | MG4: RR15_Abatement | MH4: Comm_NOIStart | MI4: GrowthOvr_1_1 | MJ4: GrowthOvr_1_2 | MK4: GrowthOvr_1_3 | ML4: GrowthOvr_1_4 | MM4: GrowthOvr_1_5 | MN4: GrowthOvr_2_1 | MO4: GrowthOvr_2_2 | MP4: GrowthOvr_2_3 | MQ4: GrowthOvr_2_4 | MR4: GrowthOvr_2_5 | MS4: GrowthOvr_3_1 | MT4: GrowthOvr_3_2 | MU4: GrowthOvr_3_3 | MV4: GrowthOvr_3_4 | MW4: GrowthOvr_3_5 | MX4: GrowthOvr_4_1 | MY4: GrowthOvr_4_2 | MZ4: GrowthOvr_4_3 | NA4: GrowthOvr_4_4 | NB4: GrowthOvr_4_5 | NC4: GrowthOvr_5_1 | ND4: GrowthOvr_5_2 | NE4: GrowthOvr_5_3 | NF4: GrowthOvr_5_4 | NG4: GrowthOvr_5_5 | NH4: Bud_Land | NI4: Bud_Land_Curve | NJ4: Bud_Shell | NK4: Bud_Shell_Curve | NL4: Bud_Sitework | NM4: Bud_Sitework_Curve | NN4: Bud_Parking | NO4: Bud_Parking_Curve | NP4: Bud_FFE | NQ4: Bud_FFE_Curve | NR4: Bud_GCFee | NS4: Bud_GCFee_Curve | NT4: Bud_HardContPct | NU4: Bud_AE | NV4: Bud_AE_Curve | NW4: Bud_Permits | NX4: Bud_Permits_Curve | NY4: Bud_Legal | NZ4: Bud_Legal_Curve | OA4: Bud_Mktg | OB4: Bud_Mktg_Curve | OC4: Bud_DevFee | OD4: Bud_DevFee_Curve | OE4: Bud_TaxInsConst | OF4: Bud_TaxInsConst_Curve | OG4: Bud_SoftContPct
A5: 1 | B5: 1-2A | C5: Site 1 - Bldg 2A | D5: 2026-06-23 | E5: seed | F5: initial seed record | G5: =Cockpit!$B$13 | H5: =Cockpit!$B$14 | I5: =Cockpit!$B$15 | J5: =Cockpit!$B$16 | K5: =Cockpit!$B$17 | L5: =Cockpit!$B$18 | M5: =Cockpit!$B$19 | N5: =Cockpit!$B$20 | O5: =Cockpit!$B$21 | P5: =Cockpit!$B$24 | Q5: =Cockpit!$B$25 | R5: =Cockpit!$B$26 | S5: =Cockpit!$B$27 | T5: =Cockpit!$B$28 | U5: =Cockpit!$B$29 | V5: =Cockpit!$B$30 | W5: =Cockpit!$B$32 | X5: =Cockpit!$B$33 | Y5: =Cockpit!$A$37 | Z5: =Cockpit!$B$37 | AA5: =Cockpit!$C$37 | AB5: =Cockpit!$D$37 | AC5: =Cockpit!$E$37 | AD5: =Cockpit!$A$38 | AE5: =Cockpit!$B$38 | AF5: =Cockpit!$C$38 | AG5: =Cockpit!$D$38 | AH5: =Cockpit!$E$38 | AI5: =Cockpit!$A$39 | AJ5: =Cockpit!$B$39 | AK5: =Cockpit!$C$39 | AL5: =Cockpit!$D$39 | AM5: =Cockpit!$E$39 | AN5: =Cockpit!$A$40 | AO5: =Cockpit!$B$40 | AP5: =Cockpit!$C$40 | AQ5: =Cockpit!$D$40 | AR5: =Cockpit!$E$40 | AS5: =Cockpit!$A$41 | AT5: =Cockpit!$B$41 | AU5: =Cockpit!$C$41 | AV5: =Cockpit!$D$41 | AW5: =Cockpit!$E$41 | AX5: =Cockpit!$A$42 | AY5: =Cockpit!$B$42 | AZ5: =Cockpit!$C$42 | BA5: =Cockpit!$D$42 | BB5: =Cockpit!$E$42 | BC5: =Cockpit!$A$43 | BD5: =Cockpit!$B$43 | BE5: =Cockpit!$C$43 | BF5: =Cockpit!$D$43 | BG5: =Cockpit!$E$43 | BH5: =Cockpit!$A$44 | BI5: =Cockpit!$B$44 | BJ5: =Cockpit!$C$44 | BK5: =Cockpit!$D$44 | BL5: =Cockpit!$E$44 | BM5: =Cockpit!$A$45 | BN5: =Cockpit!$B$45 | BO5: =Cockpit!$C$45 | BP5: =Cockpit!$D$45 | BQ5: =Cockpit!$E$45 | BR5: =Cockpit!$A$46 | BS5: =Cockpit!$B$46 | BT5: =Cockpit!$C$46 | BU5: =Cockpit!$D$46 | BV5: =Cockpit!$E$46 | BW5: =Cockpit!$A$47 | BX5: =Cockpit!$B$47 | BY5: =Cockpit!$C$47 | BZ5: =Cockpit!$D$47 | CA5: =Cockpit!$E$47 | CB5: =Cockpit!$A$48 | CC5: =Cockpit!$B$48 | CD5: =Cockpit!$C$48 | CE5: =Cockpit!$D$48 | CF5: =Cockpit!$E$48 | CG5: =Cockpit!$A$49 | CH5: =Cockpit!$B$49 | CI5: =Cockpit!$C$49 | CJ5: =Cockpit!$D$49 | CK5: =Cockpit!$E$49 | CL5: =Cockpit!$A$50 | CM5: =Cockpit!$B$50 | CN5: =Cockpit!$C$50 | CO5: =Cockpit!$D$50 | CP5: =Cockpit!$E$50 | CQ5: =Cockpit!$A$51 | CR5: =Cockpit!$B$51 | CS5: =Cockpit!$C$51 | CT5: =Cockpit!$D$51 | CU5: =Cockpit!$E$51 | CV5: =Cockpit!$B$56 | CW5: =Cockpit!$B$58 | CX5: =Cockpit!$B$59 | CY5: =Cockpit!$B$60 | CZ5: =Cockpit!$B$61 | DA5: =Cockpit!$B$62 | DB5: =Cockpit!$B$63 | DC5: =Cockpit!$B$64 | DD5: =Cockpit!$B$65 | DE5: =Cockpit!$B$66 | DF5: =Cockpit!$B$70 | DG5: =Cockpit!$C$70 | DH5: =Cockpit!$D$70 | DI5: =Cockpit!$B$71 | DJ5: =Cockpit!$C$71 | DK5: =Cockpit!$D$71 | DL5: =Cockpit!$B$72 | DM5: =Cockpit!$C$72 | DN5: =Cockpit!$D$72 | DO5: =Cockpit!$B$73 | DP5: =Cockpit!$C$73 | DQ5: =Cockpit!$D$73 | DR5: =Cockpit!$B$76 | DS5: =Cockpit!$B$78 | DT5: =Cockpit!$C$78 | DU5: =Cockpit!$B$79 | DV5: =Cockpit!$C$79 | DW5: =Cockpit!$B$80 | DX5: =Cockpit!$C$80 | DY5: =Cockpit!$B$81 | DZ5: =Cockpit!$C$81 | EA5: =Cockpit!$B$82 | EB5: =Cockpit!$C$82 | EC5: =Cockpit!$B$83 | ED5: =Cockpit!$C$83 | EE5: =Cockpit!$B$85 | EF5: =Cockpit!$C$85 | EG5: =Cockpit!$B$86 | EH5: =Cockpit!$C$86 | EI5: =Cockpit!$B$87 | EJ5: =Cockpit!$C$87 | EK5: =Cockpit!$C$88 | EL5: =Cockpit!$C$89 | EM5: =Cockpit!$B$93 | EN5: =Cockpit!$B$94 | EO5: =Cockpit!$B$98 | EP5: =Cockpit!$B$99 | EQ5: =Cockpit!$B$100 | ER5: =Cockpit!$B$101 | ES5: =Cockpit!$B$102 | ET5: =Cockpit!$B$103 | EU5: =Cockpit!$A$106 | EV5: =Cockpit!$B$106 | EW5: =Cockpit!$D$106 | EX5: =Cockpit!$E$106 | EY5: =Cockpit!$F$106 | EZ5: =Cockpit!$H$106 | FA5: =Cockpit!$I$106 | FB5: =Cockpit!$J$106 | FC5: =Cockpit!$K$106 | FD5: =Cockpit!$L$106 | FE5: =Cockpit!$N$106 | FF5: =Cockpit!$O$106 | FG5: =Cockpit!$Q$106 | FH5: =Cockpit!$A$107 | FI5: =Cockpit!$B$107 | FJ5: =Cockpit!$D$107 | FK5: =Cockpit!$E$107 | FL5: =Cockpit!$F$107 | FM5: =Cockpit!$H$107 | FN5: =Cockpit!$I$107 | FO5: =Cockpit!$J$107 | FP5: =Cockpit!$K$107 | FQ5: =Cockpit!$L$107 | FR5: =Cockpit!$N$107 | FS5: =Cockpit!$O$107 | FT5: =Cockpit!$Q$107 | FU5: =Cockpit!$A$108 | FV5: =Cockpit!$B$108 | FW5: =Cockpit!$D$108 | FX5: =Cockpit!$E$108 | FY5: =Cockpit!$F$108 | FZ5: =Cockpit!$H$108 | GA5: =Cockpit!$I$108 | GB5: =Cockpit!$J$108 | GC5: =Cockpit!$K$108 | GD5: =Cockpit!$L$108 | GE5: =Cockpit!$N$108 | GF5: =Cockpit!$O$108 | GG5: =Cockpit!$Q$108 | GH5: =Cockpit!$A$109 | GI5: =Cockpit!$B$109 | GJ5: =Cockpit!$D$109 | GK5: =Cockpit!$E$109 | GL5: =Cockpit!$F$109 | GM5: =Cockpit!$H$109 | GN5: =Cockpit!$I$109 | GO5: =Cockpit!$J$109 | GP5: =Cockpit!$K$109 | GQ5: =Cockpit!$L$109 | GR5: =Cockpit!$N$109 | GS5: =Cockpit!$O$109 | GT5: =Cockpit!$Q$109 | GU5: =Cockpit!$A$110 | GV5: =Cockpit!$B$110 | GW5: =Cockpit!$D$110 | GX5: =Cockpit!$E$110 | GY5: =Cockpit!$F$110 | GZ5: =Cockpit!$H$110 | HA5: =Cockpit!$I$110 | HB5: =Cockpit!$J$110 | HC5: =Cockpit!$K$110 | HD5: =Cockpit!$L$110 | HE5: =Cockpit!$N$110 | HF5: =Cockpit!$O$110 | HG5: =Cockpit!$Q$110 | HH5: =Cockpit!$A$111 | HI5: =Cockpit!$B$111 | HJ5: =Cockpit!$D$111 | HK5: =Cockpit!$E$111 | HL5: =Cockpit!$F$111 | HM5: =Cockpit!$H$111 | HN5: =Cockpit!$I$111 | HO5: =Cockpit!$J$111 | HP5: =Cockpit!$K$111 | HQ5: =Cockpit!$L$111 | HR5: =Cockpit!$N$111 | HS5: =Cockpit!$O$111 | HT5: =Cockpit!$Q$111 | HU5: =Cockpit!$A$112 | HV5: =Cockpit!$B$112 | HW5: =Cockpit!$D$112 | HX5: =Cockpit!$E$112 | HY5: =Cockpit!$F$112 | HZ5: =Cockpit!$H$112 | IA5: =Cockpit!$I$112 | IB5: =Cockpit!$J$112 | IC5: =Cockpit!$K$112 | ID5: =Cockpit!$L$112 | IE5: =Cockpit!$N$112 | IF5: =Cockpit!$O$112 | IG5: =Cockpit!$Q$112 | IH5: =Cockpit!$A$113 | II5: =Cockpit!$B$113 | IJ5: =Cockpit!$D$113 | IK5: =Cockpit!$E$113 | IL5: =Cockpit!$F$113 | IM5: =Cockpit!$H$113 | IN5: =Cockpit!$I$113 | IO5: =Cockpit!$J$113 | IP5: =Cockpit!$K$113 | IQ5: =Cockpit!$L$113 | IR5: =Cockpit!$N$113 | IS5: =Cockpit!$O$113 | IT5: =Cockpit!$Q$113 | IU5: =Cockpit!$A$114 | IV5: =Cockpit!$B$114 | IW5: =Cockpit!$D$114 | IX5: =Cockpit!$E$114 | IY5: =Cockpit!$F$114 | IZ5: =Cockpit!$H$114 | JA5: =Cockpit!$I$114 | JB5: =Cockpit!$J$114 | JC5: =Cockpit!$K$114 | JD5: =Cockpit!$L$114 | JE5: =Cockpit!$N$114 | JF5: =Cockpit!$O$114 | JG5: =Cockpit!$Q$114 | JH5: =Cockpit!$A$115 | JI5: =Cockpit!$B$115 | JJ5: =Cockpit!$D$115 | JK5: =Cockpit!$E$115 | JL5: =Cockpit!$F$115 | JM5: =Cockpit!$H$115 | JN5: =Cockpit!$I$115 | JO5: =Cockpit!$J$115 | JP5: =Cockpit!$K$115 | JQ5: =Cockpit!$L$115 | JR5: =Cockpit!$N$115 | JS5: =Cockpit!$O$115 | JT5: =Cockpit!$Q$115 | JU5: =Cockpit!$A$116 | JV5: =Cockpit!$B$116 | JW5: =Cockpit!$D$116 | JX5: =Cockpit!$E$116 | JY5: =Cockpit!$F$116 | JZ5: =Cockpit!$H$116 | KA5: =Cockpit!$I$116 | KB5: =Cockpit!$J$116 | KC5: =Cockpit!$K$116 | KD5: =Cockpit!$L$116 | KE5: =Cockpit!$N$116 | KF5: =Cockpit!$O$116 | KG5: =Cockpit!$Q$116 | KH5: =Cockpit!$A$117 | KI5: =Cockpit!$B$117 | KJ5: =Cockpit!$D$117 | KK5: =Cockpit!$E$117 | KL5: =Cockpit!$F$117 | KM5: =Cockpit!$H$117 | KN5: =Cockpit!$I$117 | KO5: =Cockpit!$J$117 | KP5: =Cockpit!$K$117 | KQ5: =Cockpit!$L$117 | KR5: =Cockpit!$N$117 | KS5: =Cockpit!$O$117 | KT5: =Cockpit!$Q$117 | KU5: =Cockpit!$A$118 | KV5: =Cockpit!$B$118 | KW5: =Cockpit!$D$118 | KX5: =Cockpit!$E$118 | KY5: =Cockpit!$F$118 | KZ5: =Cockpit!$H$118 | LA5: =Cockpit!$I$118 | LB5: =Cockpit!$J$118 | LC5: =Cockpit!$K$118 | LD5: =Cockpit!$L$118 | LE5: =Cockpit!$N$118 | LF5: =Cockpit!$O$118 | LG5: =Cockpit!$Q$118 | LH5: =Cockpit!$A$119 | LI5: =Cockpit!$B$119 | LJ5: =Cockpit!$D$119 | LK5: =Cockpit!$E$119 | LL5: =Cockpit!$F$119 | LM5: =Cockpit!$H$119 | LN5: =Cockpit!$I$119 | LO5: =Cockpit!$J$119 | LP5: =Cockpit!$K$119 | LQ5: =Cockpit!$L$119 | LR5: =Cockpit!$N$119 | LS5: =Cockpit!$O$119 | LT5: =Cockpit!$Q$119 | LU5: =Cockpit!$A$120 | LV5: =Cockpit!$B$120 | LW5: =Cockpit!$D$120 | LX5: =Cockpit!$E$120 | LY5: =Cockpit!$F$120 | LZ5: =Cockpit!$H$120 | MA5: =Cockpit!$I$120 | MB5: =Cockpit!$J$120 | MC5: =Cockpit!$K$120 | MD5: =Cockpit!$L$120 | ME5: =Cockpit!$N$120 | MF5: =Cockpit!$O$120 | MG5: =Cockpit!$Q$120 | MH5: =Cockpit!$B$122 | MI5: =Cockpit!$I$127 | MJ5: =Cockpit!$J$127 | MK5: =Cockpit!$K$127 | ML5: =Cockpit!$L$127 | MM5: =Cockpit!$M$127 | MN5: =Cockpit!$I$128 | MO5: =Cockpit!$J$128 | MP5: =Cockpit!$K$128 | MQ5: =Cockpit!$L$128 | MR5: =Cockpit!$M$128 | MS5: =Cockpit!$I$129 | MT5: =Cockpit!$J$129 | MU5: =Cockpit!$K$129 | MV5: =Cockpit!$L$129 | MW5: =Cockpit!$M$129 | MX5: =Cockpit!$I$130 | MY5: =Cockpit!$J$130 | MZ5: =Cockpit!$K$130 | NA5: =Cockpit!$L$130 | NB5: =Cockpit!$M$130 | NC5: =Cockpit!$I$131 | ND5: =Cockpit!$J$131 | NE5: =Cockpit!$K$131 | NF5: =Cockpit!$L$131 | NG5: =Cockpit!$M$131 | NH5: =Cockpit!$B$136 | NI5: =Cockpit!$E$136 | NJ5: =Cockpit!$B$137 | NK5: =Cockpit!$E$137 | NL5: =Cockpit!$B$138 | NM5: =Cockpit!$E$138 | NN5: =Cockpit!$B$139 | NO5: =Cockpit!$E$139 | NP5: =Cockpit!$B$140 | NQ5: =Cockpit!$E$140 | NR5: =Cockpit!$B$141 | NS5: =Cockpit!$E$141 | NT5: =Cockpit!$B$142 | NU5: =Cockpit!$B$144 | NV5: =Cockpit!$E$144 | NW5: =Cockpit!$B$145 | NX5: =Cockpit!$E$145 | NY5: =Cockpit!$B$146 | NZ5: =Cockpit!$E$146 | OA5: =Cockpit!$B$147 | OB5: =Cockpit!$E$147 | OC5: =Cockpit!$B$148 | OD5: =Cockpit!$E$148 | OE5: =Cockpit!$B$149 | OF5: =Cockpit!$E$149 | OG5: =Cockpit!$B$150
A6: 2 | B6: 1-2B | C6: Site 1 - Bldg 2B | D6: 2026-06-23 | E6: seed | F6: initial seed record
A7: 3 | B7: 3-1B | C7: Site 3 - Bldg 1B | D7: 2026-06-23 | E7: seed | F7: initial seed record

Sheet All Phases
A1: ALL PHASES - program roll-up (latest record per Phase, read-only)
A3: Phase | B3: Site | C3: Use | D3: Units | E3: NSF | F3: EGI | G3: NOI | H3: OpEx Ratio | I3: Total Dev Cost | J3: Cost/Unit | K3: Cost/GSF | L3: NOI/Unit
A4: =IF(Lists!$A$2="","",Lists!$A$2) | B4: =IFERROR(IF(Lists!$A$2="","",INDEX(Database!$H:$H,MATCH(MAXIFS(Database!$A:$A,Database!$B:$B,Lists!$A$2),Database!$A:$A,0))),"") | C4: =IFERROR(IF(Lists!$A$2="","",IF(INDEX(Database!$J:$J,MATCH(MAXIFS(Database!$A:$A,Database!$B:$B,Lists!$A$2),Database!$A:$A,0))="Yes","Mixed-Use","Residential")),"") | D4: =IFERROR(IF(Lists!$A$2="","",N(INDEX(Database!$AA:$AA,MATCH(MAXIFS(Database!$A:$A,Database!$B:$B,Lists!$A$2),Database!$A:$A,0)))+N(INDEX(Database!$AF:$AF,MATCH(MAXIFS(Database!$A:$A,Database!$B:$B,Lists!$A$2),Database!$A:$A,0)))+N(INDEX(Database!$AK:$AK,MATCH(MAXIFS(Database!$A:$A,Database!$B:$B,Lists!$A$2),Database!$A:$A,0)))+N(INDEX(Database!$AP:$AP,MATCH(MAXIFS(Database!$A:$A,Database!$B:$B,Lists!$A$2),Database!$A:$A,0)))+N(INDEX(Database!$AU:$AU,MATCH(MAXIFS(Database!$A:$A,Database!$B:$B,Lists!$A$2),Database!$A:$A,0)))+N(INDEX(Database!$AZ:$AZ,MATCH(MAXIFS(Database!$A:$A,Database!$B:$B,Lists!$A$2),Database!$A:$A,0)))+N(INDEX(Database!$BE:$BE,MATCH(MAXIFS(Database!$A:$A,Database!$B:$B,Lists!$A$2),Database!$A:$A,0)))+N(INDEX(Database!$BJ:$BJ,MATCH(MAXIFS(Database!$A:$A,Database!$B:$B,Lists!$A$2),Database!$A:$A,0)))+N(INDEX(Database!$BO:$BO,MATCH(MAXIFS(Database!$A:$A,Database!$B:$B,Lists!$A$2),Database!$A:$A,0)))+N(INDEX(Database!$BT:$BT,MATCH(MAXIFS(Database!$A:$A,Database!$B:$B,Lists!$A$2),Database!$A:$A,0)))+N(INDEX(Database!$BY:$BY,MATCH(MAXIFS(Database!$A:$A,Database!$B:$B,Lists!$A$2),Database!$A:$A,0)))+N(INDEX(Database!$CD:$CD,MATCH(MAXIFS(Database!$A:$A,Database!$B:$B,Lists!$A$2),Database!$A:$A,0)))+N(INDEX(Database!$CI:$CI,MATCH(MAXIFS(Database!$A:$A,Database!$B:$B,Lists!$A$2),Database!$A:$A,0)))+N(INDEX(Database!$CN:$CN,MATCH(MAXIFS(Database!$A:$A,Database!$B:$B,Lists!$A$2),Database!$A:$A,0)))+N(INDEX(Database!$CS:$CS,MATCH(MAXIFS(Database!$A:$A,Database!$B:$B,Lists!$A$2),Database!$A:$A,0)))),"") | E4: =IFERROR(IF(Lists!$A$2="","",INDEX(Database!$M:$M,MATCH(MAXIFS(Database!$A:$A,Database!$B:$B,Lists!$A$2),Database!$A:$A,0))),"") | F4: =IF(Lists!$A$2="","","-") | G4: =IF(Lists!$A$2="","","-") | H4: =IF(Lists!$A$2="","","-") | I4: =IF(Lists!$A$2="","","-") | J4: =IF(Lists!$A$2="","","-") | K4: =IF(Lists!$A$2="","","-") | L4: =IF(Lists!$A$2="","","-")
A5: =IF(Lists!$A$3="","",Lists!$A$3) | B5: =IFERROR(IF(Lists!$A$3="","",INDEX(Database!$H:$H,MATCH(MAXIFS(Database!$A:$A,Database!$B:$B,Lists!$A$3),Database!$A:$A,0))),"") | C5: =IFERROR(IF(Lists!$A$3="","",IF(INDEX(Database!$J:$J,MATCH(MAXIFS(Database!$A:$A,Database!$B:$B,Lists!$A$3),Database!$A:$A,0))="Yes","Mixed-Use","Residential")),"") | D5: =IFERROR(IF(Lists!$A$3="","",N(INDEX(Database!$AA:$AA,MATCH(MAXIFS(Database!$A:$A,Database!$B:$B,Lists!$A$3),Database!$A:$A,0)))+N(INDEX(Database!$AF:$AF,MATCH(MAXIFS(Database!$A:$A,Database!$B:$B,Lists!$A$3),Database!$A:$A,0)))+N(INDEX(Database!$AK:$AK,MATCH(MAXIFS(Database!$A:$A,Database!$B:$B,Lists!$A$3),Database!$A:$A,0)))+N(INDEX(Database!$AP:$AP,MATCH(MAXIFS(Database!$A:$A,Database!$B:$B,Lists!$A$3),Database!$A:$A,0)))+N(INDEX(Database!$AU:$AU,MATCH(MAXIFS(Database!$A:$A,Database!$B:$B,Lists!$A$3),Database!$A:$A,0)))+N(INDEX(Database!$AZ:$AZ,MATCH(MAXIFS(Database!$A:$A,Database!$B:$B,Lists!$A$3),Database!$A:$A,0)))+N(INDEX(Database!$BE:$BE,MATCH(MAXIFS(Database!$A:$A,Database!$B:$B,Lists!$A$3),Database!$A:$A,0)))+N(INDEX(Database!$BJ:$BJ,MATCH(MAXIFS(Database!$A:$A,Database!$B:$B,Lists!$A$3),Database!$A:$A,0)))+N(INDEX(Database!$BO:$BO,MATCH(MAXIFS(Database!$A:$A,Database!$B:$B,Lists!$A$3),Database!$A:$A,0)))+N(INDEX(Database!$BT:$BT,MATCH(MAXIFS(Database!$A:$A,Database!$B:$B,Lists!$A$3),Database!$A:$A,0)))+N(INDEX(Database!$BY:$BY,MATCH(MAXIFS(Database!$A:$A,Database!$B:$B,Lists!$A$3),Database!$A:$A,0)))+N(INDEX(Database!$CD:$CD,MATCH(MAXIFS(Database!$A:$A,Database!$B:$B,Lists!$A$3),Database!$A:$A,0)))+N(INDEX(Database!$CI:$CI,MATCH(MAXIFS(Database!$A:$A,Database!$B:$B,Lists!$A$3),Database!$A:$A,0)))+N(INDEX(Database!$CN:$CN,MATCH(MAXIFS(Database!$A:$A,Database!$B:$B,Lists!$A$3),Database!$A:$A,0)))+N(INDEX(Database!$CS:$CS,MATCH(MAXIFS(Database!$A:$A,Database!$B:$B,Lists!$A$3),Database!$A:$A,0)))),"") | E5: =IFERROR(IF(Lists!$A$3="","",INDEX(Database!$M:$M,MATCH(MAXIFS(Database!$A:$A,Database!$B:$B,Lists!$A$3),Database!$A:$A,0))),"") | F5: =IF(Lists!$A$3="","","-") | G5: =IF(Lists!$A$3="","","-") | H5: =IF(Lists!$A$3="","","-") | I5: =IF(Lists!$A$3="","","-") | J5: =IF(Lists!$A$3="","","-") | K5: =IF(Lists!$A$3="","","-") | L5: =IF(Lists!$A$3="","","-")
A6: =IF(Lists!$A$4="","",Lists!$A$4) | B6: =IFERROR(IF(Lists!$A$4="","",INDEX(Database!$H:$H,MATCH(MAXIFS(Database!$A:$A,Database!$B:$B,Lists!$A$4),Database!$A:$A,0))),"") | C6: =IFERROR(IF(Lists!$A$4="","",IF(INDEX(Database!$J:$J,MATCH(MAXIFS(Database!$A:$A,Database!$B:$B,Lists!$A$4),Database!$A:$A,0))="Yes","Mixed-Use","Residential")),"") | D6: =IFERROR(IF(Lists!$A$4="","",N(INDEX(Database!$AA:$AA,MATCH(MAXIFS(Database!$A:$A,Database!$B:$B,Lists!$A$4),Database!$A:$A,0)))+N(INDEX(Database!$AF:$AF,MATCH(MAXIFS(Database!$A:$A,Database!$B:$B,Lists!$A$4),Database!$A:$A,0)))+N(INDEX(Database!$AK:$AK,MATCH(MAXIFS(Database!$A:$A,Database!$B:$B,Lists!$A$4),Database!$A:$A,0)))+N(INDEX(Database!$AP:$AP,MATCH(MAXIFS(Database!$A:$A,Database!$B:$B,Lists!$A$4),Database!$A:$A,0)))+N(INDEX(Database!$AU:$AU,MATCH(MAXIFS(Database!$A:$A,Database!$B:$B,Lists!$A$4),Database!$A:$A,0)))+N(INDEX(Database!$AZ:$AZ,MATCH(MAXIFS(Database!$A:$A,Database!$B:$B,Lists!$A$4),Database!$A:$A,0)))+N(INDEX(Database!$BE:$BE,MATCH(MAXIFS(Database!$A:$A,Database!$B:$B,Lists!$A$4),Database!$A:$A,0)))+N(INDEX(Database!$BJ:$BJ,MATCH(MAXIFS(Database!$A:$A,Database!$B:$B,Lists!$A$4),Database!$A:$A,0)))+N(INDEX(Database!$BO:$BO,MATCH(MAXIFS(Database!$A:$A,Database!$B:$B,Lists!$A$4),Database!$A:$A,0)))+N(INDEX(Database!$BT:$BT,MATCH(MAXIFS(Database!$A:$A,Database!$B:$B,Lists!$A$4),Database!$A:$A,0)))+N(INDEX(Database!$BY:$BY,MATCH(MAXIFS(Database!$A:$A,Database!$B:$B,Lists!$A$4),Database!$A:$A,0)))+N(INDEX(Database!$CD:$CD,MATCH(MAXIFS(Database!$A:$A,Database!$B:$B,Lists!$A$4),Database!$A:$A,0)))+N(INDEX(Database!$CI:$CI,MATCH(MAXIFS(Database!$A:$A,Database!$B:$B,Lists!$A$4),Database!$A:$A,0)))+N(INDEX(Database!$CN:$CN,MATCH(MAXIFS(Database!$A:$A,Database!$B:$B,Lists!$A$4),Database!$A:$A,0)))+N(INDEX(Database!$CS:$CS,MATCH(MAXIFS(Database!$A:$A,Database!$B:$B,Lists!$A$4),Database!$A:$A,0)))),"") | E6: =IFERROR(IF(Lists!$A$4="","",INDEX(Database!$M:$M,MATCH(MAXIFS(Database!$A:$A,Database!$B:$B,Lists!$A$4),Database!$A:$A,0))),"") | F6: =IF(Lists!$A$4="","","-") | G6: =IF(Lists!$A$4="","","-") | H6: =IF(Lists!$A$4="","","-") | I6: =IF(Lists!$A$4="","","-") | J6: =IF(Lists!$A$4="","","-") | K6: =IF(Lists!$A$4="","","-") | L6: =IF(Lists!$A$4="","","-")
A7: =IF(Lists!$A$5="","",Lists!$A$5) | B7: =IFERROR(IF(Lists!$A$5="","",INDEX(Database!$H:$H,MATCH(MAXIFS(Database!$A:$A,Database!$B:$B,Lists!$A$5),Database!$A:$A,0))),"") | C7: =IFERROR(IF(Lists!$A$5="","",IF(INDEX(Database!$J:$J,MATCH(MAXIFS(Database!$A:$A,Database!$B:$B,Lists!$A$5),Database!$A:$A,0))="Yes","Mixed-Use","Residential")),"") | D7: =IFERROR(IF(Lists!$A$5="","",N(INDEX(Database!$AA:$AA,MATCH(MAXIFS(Database!$A:$A,Database!$B:$B,Lists!$A$5),Database!$A:$A,0)))+N(INDEX(Database!$AF:$AF,MATCH(MAXIFS(Database!$A:$A,Database!$B:$B,Lists!$A$5),Database!$A:$A,0)))+N(INDEX(Database!$AK:$AK,MATCH(MAXIFS(Database!$A:$A,Database!$B:$B,Lists!$A$5),Database!$A:$A,0)))+N(INDEX(Database!$AP:$AP,MATCH(MAXIFS(Database!$A:$A,Database!$B:$B,Lists!$A$5),Database!$A:$A,0)))+N(INDEX(Database!$AU:$AU,MATCH(MAXIFS(Database!$A:$A,Database!$B:$B,Lists!$A$5),Database!$A:$A,0)))+N(INDEX(Database!$AZ:$AZ,MATCH(MAXIFS(Database!$A:$A,Database!$B:$B,Lists!$A$5),Database!$A:$A,0)))+N(INDEX(Database!$BE:$BE,MATCH(MAXIFS(Database!$A:$A,Database!$B:$B,Lists!$A$5),Database!$A:$A,0)))+N(INDEX(Database!$BJ:$BJ,MATCH(MAXIFS(Database!$A:$A,Database!$B:$B,Lists!$A$5),Database!$A:$A,0)))+N(INDEX(Database!$BO:$BO,MATCH(MAXIFS(Database!$A:$A,Database!$B:$B,Lists!$A$5),Database!$A:$A,0)))+N(INDEX(Database!$BT:$BT,MATCH(MAXIFS(Database!$A:$A,Database!$B:$B,Lists!$A$5),Database!$A:$A,0)))+N(INDEX(Database!$BY:$BY,MATCH(MAXIFS(Database!$A:$A,Database!$B:$B,Lists!$A$5),Database!$A:$A,0)))+N(INDEX(Database!$CD:$CD,MATCH(MAXIFS(Database!$A:$A,Database!$B:$B,Lists!$A$5),Database!$A:$A,0)))+N(INDEX(Database!$CI:$CI,MATCH(MAXIFS(Database!$A:$A,Database!$B:$B,Lists!$A$5),Database!$A:$A,0)))+N(INDEX(Database!$CN:$CN,MATCH(MAXIFS(Database!$A:$A,Database!$B:$B,Lists!$A$5),Database!$A:$A,0)))+N(INDEX(Database!$CS:$CS,MATCH(MAXIFS(Database!$A:$A,Database!$B:$B,Lists!$A$5),Database!$A:$A,0)))),"") | E7: =IFERROR(IF(Lists!$A$5="","",INDEX(Database!$M:$M,MATCH(MAXIFS(Database!$A:$A,Database!$B:$B,Lists!$A$5),Database!$A:$A,0))),"") | F7: =IF(Lists!$A$5="","","-") | G7: =IF(Lists!$A$5="","","-") | H7: =IF(Lists!$A$5="","","-") | I7: =IF(Lists!$A$5="","","-") | J7: =IF(Lists!$A$5="","","-") | K7: =IF(Lists!$A$5="","","-") | L7: =IF(Lists!$A$5="","","-")
A8: =IF(Lists!$A$6="","",Lists!$A$6) | B8: =IFERROR(IF(Lists!$A$6="","",INDEX(Database!$H:$H,MATCH(MAXIFS(Database!$A:$A,Database!$B:$B,Lists!$A$6),Database!$A:$A,0))),"") | C8: =IFERROR(IF(Lists!$A$6="","",IF(INDEX(Database!$J:$J,MATCH(MAXIFS(Database!$A:$A,Database!$B:$B,Lists!$A$6),Database!$A:$A,0))="Yes","Mixed-Use","Residential")),"") | D8: =IFERROR(IF(Lists!$A$6="","",N(INDEX(Database!$AA:$AA,MATCH(MAXIFS(Database!$A:$A,Database!$B:$B,Lists!$A$6),Database!$A:$A,0)))+N(INDEX(Database!$AF:$AF,MATCH(MAXIFS(Database!$A:$A,Database!$B:$B,Lists!$A$6),Database!$A:$A,0)))+N(INDEX(Database!$AK:$AK,MATCH(MAXIFS(Database!$A:$A,Database!$B:$B,Lists!$A$6),Database!$A:$A,0)))+N(INDEX(Database!$AP:$AP,MATCH(MAXIFS(Database!$A:$A,Database!$B:$B,Lists!$A$6),Database!$A:$A,0)))+N(INDEX(Database!$AU:$AU,MATCH(MAXIFS(Database!$A:$A,Database!$B:$B,Lists!$A$6),Database!$A:$A,0)))+N(INDEX(Database!$AZ:$AZ,MATCH(MAXIFS(Database!$A:$A,Database!$B:$B,Lists!$A$6),Database!$A:$A,0)))+N(INDEX(Database!$BE:$BE,MATCH(MAXIFS(Database!$A:$A,Database!$B:$B,Lists!$A$6),Database!$A:$A,0)))+N(INDEX(Database!$BJ:$BJ,MATCH(MAXIFS(Database!$A:$A,Database!$B:$B,Lists!$A$6),Database!$A:$A,0)))+N(INDEX(Database!$BO:$BO,MATCH(MAXIFS(Database!$A:$A,Database!$B:$B,Lists!$A$6),Database!$A:$A,0)))+N(INDEX(Database!$BT:$BT,MATCH(MAXIFS(Database!$A:$A,Database!$B:$B,Lists!$A$6),Database!$A:$A,0)))+N(INDEX(Database!$BY:$BY,MATCH(MAXIFS(Database!$A:$A,Database!$B:$B,Lists!$A$6),Database!$A:$A,0)))+N(INDEX(Database!$CD:$CD,MATCH(MAXIFS(Database!$A:$A,Database!$B:$B,Lists!$A$6),Database!$A:$A,0)))+N(INDEX(Database!$CI:$CI,MATCH(MAXIFS(Database!$A:$A,Database!$B:$B,Lists!$A$6),Database!$A:$A,0)))+N(INDEX(Database!$CN:$CN,MATCH(MAXIFS(Database!$A:$A,Database!$B:$B,Lists!$A$6),Database!$A:$A,0)))+N(INDEX(Database!$CS:$CS,MATCH(MAXIFS(Database!$A:$A,Database!$B:$B,Lists!$A$6),Database!$A:$A,0)))),"") | E8: =IFERROR(IF(Lists!$A$6="","",INDEX(Database!$M:$M,MATCH(MAXIFS(Database!$A:$A,Database!$B:$B,Lists!$A$6),Database!$A:$A,0))),"") | F8: =IF(Lists!$A$6="","","-") | G8: =IF(Lists!$A$6="","","-") | H8: =IF(Lists!$A$6="","","-") | I8: =IF(Lists!$A$6="","","-") | J8: =IF(Lists!$A$6="","","-") | K8: =IF(Lists!$A$6="","","-") | L8: =IF(Lists!$A$6="","","-")
A9: =IF(Lists!$A$7="","",Lists!$A$7) | B9: =IFERROR(IF(Lists!$A$7="","",INDEX(Database!$H:$H,MATCH(MAXIFS(Database!$A:$A,Database!$B:$B,Lists!$A$7),Database!$A:$A,0))),"") | C9: =IFERROR(IF(Lists!$A$7="","",IF(INDEX(Database!$J:$J,MATCH(MAXIFS(Database!$A:$A,Database!$B:$B,Lists!$A$7),Database!$A:$A,0))="Yes","Mixed-Use","Residential")),"") | D9: =IFERROR(IF(Lists!$A$7="","",N(INDEX(Database!$AA:$AA,MATCH(MAXIFS(Database!$A:$A,Database!$B:$B,Lists!$A$7),Database!$A:$A,0)))+N(INDEX(Database!$AF:$AF,MATCH(MAXIFS(Database!$A:$A,Database!$B:$B,Lists!$A$7),Database!$A:$A,0)))+N(INDEX(Database!$AK:$AK,MATCH(MAXIFS(Database!$A:$A,Database!$B:$B,Lists!$A$7),Database!$A:$A,0)))+N(INDEX(Database!$AP:$AP,MATCH(MAXIFS(Database!$A:$A,Database!$B:$B,Lists!$A$7),Database!$A:$A,0)))+N(INDEX(Database!$AU:$AU,MATCH(MAXIFS(Database!$A:$A,Database!$B:$B,Lists!$A$7),Database!$A:$A,0)))+N(INDEX(Database!$AZ:$AZ,MATCH(MAXIFS(Database!$A:$A,Database!$B:$B,Lists!$A$7),Database!$A:$A,0)))+N(INDEX(Database!$BE:$BE,MATCH(MAXIFS(Database!$A:$A,Database!$B:$B,Lists!$A$7),Database!$A:$A,0)))+N(INDEX(Database!$BJ:$BJ,MATCH(MAXIFS(Database!$A:$A,Database!$B:$B,Lists!$A$7),Database!$A:$A,0)))+N(INDEX(Database!$BO:$BO,MATCH(MAXIFS(Database!$A:$A,Database!$B:$B,Lists!$A$7),Database!$A:$A,0)))+N(INDEX(Database!$BT:$BT,MATCH(MAXIFS(Database!$A:$A,Database!$B:$B,Lists!$A$7),Database!$A:$A,0)))+N(INDEX(Database!$BY:$BY,MATCH(MAXIFS(Database!$A:$A,Database!$B:$B,Lists!$A$7),Database!$A:$A,0)))+N(INDEX(Database!$CD:$CD,MATCH(MAXIFS(Database!$A:$A,Database!$B:$B,Lists!$A$7),Database!$A:$A,0)))+N(INDEX(Database!$CI:$CI,MATCH(MAXIFS(Database!$A:$A,Database!$B:$B,Lists!$A$7),Database!$A:$A,0)))+N(INDEX(Database!$CN:$CN,MATCH(MAXIFS(Database!$A:$A,Database!$B:$B,Lists!$A$7),Database!$A:$A,0)))+N(INDEX(Database!$CS:$CS,MATCH(MAXIFS(Database!$A:$A,Database!$B:$B,Lists!$A$7),Database!$A:$A,0)))),"") | E9: =IFERROR(IF(Lists!$A$7="","",INDEX(Database!$M:$M,MATCH(MAXIFS(Database!$A:$A,Database!$B:$B,Lists!$A$7),Database!$A:$A,0))),"") | F9: =IF(Lists!$A$7="","","-") | G9: =IF(Lists!$A$7="","","-") | H9: =IF(Lists!$A$7="","","-") | I9: =IF(Lists!$A$7="","","-") | J9: =IF(Lists!$A$7="","","-") | K9: =IF(Lists!$A$7="","","-") | L9: =IF(Lists!$A$7="","","-")
A10: =IF(Lists!$A$8="","",Lists!$A$8) | B10: =IFERROR(IF(Lists!$A$8="","",INDEX(Database!$H:$H,MATCH(MAXIFS(Database!$A:$A,Database!$B:$B,Lists!$A$8),Database!$A:$A,0))),"") | C10: =IFERROR(IF(Lists!$A$8="","",IF(INDEX(Database!$J:$J,MATCH(MAXIFS(Database!$A:$A,Database!$B:$B,Lists!$A$8),Database!$A:$A,0))="Yes","Mixed-Use","Residential")),"") | D10: =IFERROR(IF(Lists!$A$8="","",N(INDEX(Database!$AA:$AA,MATCH(MAXIFS(Database!$A:$A,Database!$B:$B,Lists!$A$8),Database!$A:$A,0)))+N(INDEX(Database!$AF:$AF,MATCH(MAXIFS(Database!$A:$A,Database!$B:$B,Lists!$A$8),Database!$A:$A,0)))+N(INDEX(Database!$AK:$AK,MATCH(MAXIFS(Database!$A:$A,Database!$B:$B,Lists!$A$8),Database!$A:$A,0)))+N(INDEX(Database!$AP:$AP,MATCH(MAXIFS(Database!$A:$A,Database!$B:$B,Lists!$A$8),Database!$A:$A,0)))+N(INDEX(Database!$AU:$AU,MATCH(MAXIFS(Database!$A:$A,Database!$B:$B,Lists!$A$8),Database!$A:$A,0)))+N(INDEX(Database!$AZ:$AZ,MATCH(MAXIFS(Database!$A:$A,Database!$B:$B,Lists!$A$8),Database!$A:$A,0)))+N(INDEX(Database!$BE:$BE,MATCH(MAXIFS(Database!$A:$A,Database!$B:$B,Lists!$A$8),Database!$A:$A,0)))+N(INDEX(Database!$BJ:$BJ,MATCH(MAXIFS(Database!$A:$A,Database!$B:$B,Lists!$A$8),Database!$A:$A,0)))+N(INDEX(Database!$BO:$BO,MATCH(MAXIFS(Database!$A:$A,Database!$B:$B,Lists!$A$8),Database!$A:$A,0)))+N(INDEX(Database!$BT:$BT,MATCH(MAXIFS(Database!$A:$A,Database!$B:$B,Lists!$A$8),Database!$A:$A,0)))+N(INDEX(Database!$BY:$BY,MATCH(MAXIFS(Database!$A:$A,Database!$B:$B,Lists!$A$8),Database!$A:$A,0)))+N(INDEX(Database!$CD:$CD,MATCH(MAXIFS(Database!$A:$A,Database!$B:$B,Lists!$A$8),Database!$A:$A,0)))+N(INDEX(Database!$CI:$CI,MATCH(MAXIFS(Database!$A:$A,Database!$B:$B,Lists!$A$8),Database!$A:$A,0)))+N(INDEX(Database!$CN:$CN,MATCH(MAXIFS(Database!$A:$A,Database!$B:$B,Lists!$A$8),Database!$A:$A,0)))+N(INDEX(Database!$CS:$CS,MATCH(MAXIFS(Database!$A:$A,Database!$B:$B,Lists!$A$8),Database!$A:$A,0)))),"") | E10: =IFERROR(IF(Lists!$A$8="","",INDEX(Database!$M:$M,MATCH(MAXIFS(Database!$A:$A,Database!$B:$B,Lists!$A$8),Database!$A:$A,0))),"") | F10: =IF(Lists!$A$8="","","-") | G10: =IF(Lists!$A$8="","","-") | H10: =IF(Lists!$A$8="","","-") | I10: =IF(Lists!$A$8="","","-") | J10: =IF(Lists!$A$8="","","-") | K10: =IF(Lists!$A$8="","","-") | L10: =IF(Lists!$A$8="","","-")
A11: =IF(Lists!$A$9="","",Lists!$A$9) | B11: =IFERROR(IF(Lists!$A$9="","",INDEX(Database!$H:$H,MATCH(MAXIFS(Database!$A:$A,Database!$B:$B,Lists!$A$9),Database!$A:$A,0))),"") | C11: =IFERROR(IF(Lists!$A$9="","",IF(INDEX(Database!$J:$J,MATCH(MAXIFS(Database!$A:$A,Database!$B:$B,Lists!$A$9),Database!$A:$A,0))="Yes","Mixed-Use","Residential")),"") | D11: =IFERROR(IF(Lists!$A$9="","",N(INDEX(Database!$AA:$AA,MATCH(MAXIFS(Database!$A:$A,Database!$B:$B,Lists!$A$9),Database!$A:$A,0)))+N(INDEX(Database!$AF:$AF,MATCH(MAXIFS(Database!$A:$A,Database!$B:$B,Lists!$A$9),Database!$A:$A,0)))+N(INDEX(Database!$AK:$AK,MATCH(MAXIFS(Database!$A:$A,Database!$B:$B,Lists!$A$9),Database!$A:$A,0)))+N(INDEX(Database!$AP:$AP,MATCH(MAXIFS(Database!$A:$A,Database!$B:$B,Lists!$A$9),Database!$A:$A,0)))+N(INDEX(Database!$AU:$AU,MATCH(MAXIFS(Database!$A:$A,Database!$B:$B,Lists!$A$9),Database!$A:$A,0)))+N(INDEX(Database!$AZ:$AZ,MATCH(MAXIFS(Database!$A:$A,Database!$B:$B,Lists!$A$9),Database!$A:$A,0)))+N(INDEX(Database!$BE:$BE,MATCH(MAXIFS(Database!$A:$A,Database!$B:$B,Lists!$A$9),Database!$A:$A,0)))+N(INDEX(Database!$BJ:$BJ,MATCH(MAXIFS(Database!$A:$A,Database!$B:$B,Lists!$A$9),Database!$A:$A,0)))+N(INDEX(Database!$BO:$BO,MATCH(MAXIFS(Database!$A:$A,Database!$B:$B,Lists!$A$9),Database!$A:$A,0)))+N(INDEX(Database!$BT:$BT,MATCH(MAXIFS(Database!$A:$A,Database!$B:$B,Lists!$A$9),Database!$A:$A,0)))+N(INDEX(Database!$BY:$BY,MATCH(MAXIFS(Database!$A:$A,Database!$B:$B,Lists!$A$9),Database!$A:$A,0)))+N(INDEX(Database!$CD:$CD,MATCH(MAXIFS(Database!$A:$A,Database!$B:$B,Lists!$A$9),Database!$A:$A,0)))+N(INDEX(Database!$CI:$CI,MATCH(MAXIFS(Database!$A:$A,Database!$B:$B,Lists!$A$9),Database!$A:$A,0)))+N(INDEX(Database!$CN:$CN,MATCH(MAXIFS(Database!$A:$A,Database!$B:$B,Lists!$A$9),Database!$A:$A,0)))+N(INDEX(Database!$CS:$CS,MATCH(MAXIFS(Database!$A:$A,Database!$B:$B,Lists!$A$9),Database!$A:$A,0)))),"") | E11: =IFERROR(IF(Lists!$A$9="","",INDEX(Database!$M:$M,MATCH(MAXIFS(Database!$A:$A,Database!$B:$B,Lists!$A$9),Database!$A:$A,0))),"") | F11: =IF(Lists!$A$9="","","-") | G11: =IF(Lists!$A$9="","","-") | H11: =IF(Lists!$A$9="","","-") | I11: =IF(Lists!$A$9="","","-") | J11: =IF(Lists!$A$9="","","-") | K11: =IF(Lists!$A$9="","","-") | L11: =IF(Lists!$A$9="","","-")
A12: =IF(Lists!$A$10="","",Lists!$A$10) | B12: =IFERROR(IF(Lists!$A$10="","",INDEX(Database!$H:$H,MATCH(MAXIFS(Database!$A:$A,Database!$B:$B,Lists!$A$10),Database!$A:$A,0))),"") | C12: =IFERROR(IF(Lists!$A$10="","",IF(INDEX(Database!$J:$J,MATCH(MAXIFS(Database!$A:$A,Database!$B:$B,Lists!$A$10),Database!$A:$A,0))="Yes","Mixed-Use","Residential")),"") | D12: =IFERROR(IF(Lists!$A$10="","",N(INDEX(Database!$AA:$AA,MATCH(MAXIFS(Database!$A:$A,Database!$B:$B,Lists!$A$10),Database!$A:$A,0)))+N(INDEX(Database!$AF:$AF,MATCH(MAXIFS(Database!$A:$A,Database!$B:$B,Lists!$A$10),Database!$A:$A,0)))+N(INDEX(Database!$AK:$AK,MATCH(MAXIFS(Database!$A:$A,Database!$B:$B,Lists!$A$10),Database!$A:$A,0)))+N(INDEX(Database!$AP:$AP,MATCH(MAXIFS(Database!$A:$A,Database!$B:$B,Lists!$A$10),Database!$A:$A,0)))+N(INDEX(Database!$AU:$AU,MATCH(MAXIFS(Database!$A:$A,Database!$B:$B,Lists!$A$10),Database!$A:$A,0)))+N(INDEX(Database!$AZ:$AZ,MATCH(MAXIFS(Database!$A:$A,Database!$B:$B,Lists!$A$10),Database!$A:$A,0)))+N(INDEX(Database!$BE:$BE,MATCH(MAXIFS(Database!$A:$A,Database!$B:$B,Lists!$A$10),Database!$A:$A,0)))+N(INDEX(Database!$BJ:$BJ,MATCH(MAXIFS(Database!$A:$A,Database!$B:$B,Lists!$A$10),Database!$A:$A,0)))+N(INDEX(Database!$BO:$BO,MATCH(MAXIFS(Database!$A:$A,Database!$B:$B,Lists!$A$10),Database!$A:$A,0)))+N(INDEX(Database!$BT:$BT,MATCH(MAXIFS(Database!$A:$A,Database!$B:$B,Lists!$A$10),Database!$A:$A,0)))+N(INDEX(Database!$BY:$BY,MATCH(MAXIFS(Database!$A:$A,Database!$B:$B,Lists!$A$10),Database!$A:$A,0)))+N(INDEX(Database!$CD:$CD,MATCH(MAXIFS(Database!$A:$A,Database!$B:$B,Lists!$A$10),Database!$A:$A,0)))+N(INDEX(Database!$CI:$CI,MATCH(MAXIFS(Database!$A:$A,Database!$B:$B,Lists!$A$10),Database!$A:$A,0)))+N(INDEX(Database!$CN:$CN,MATCH(MAXIFS(Database!$A:$A,Database!$B:$B,Lists!$A$10),Database!$A:$A,0)))+N(INDEX(Database!$CS:$CS,MATCH(MAXIFS(Database!$A:$A,Database!$B:$B,Lists!$A$10),Database!$A:$A,0)))),"") | E12: =IFERROR(IF(Lists!$A$10="","",INDEX(Database!$M:$M,MATCH(MAXIFS(Database!$A:$A,Database!$B:$B,Lists!$A$10),Database!$A:$A,0))),"") | F12: =IF(Lists!$A$10="","","-") | G12: =IF(Lists!$A$10="","","-") | H12: =IF(Lists!$A$10="","","-") | I12: =IF(Lists!$A$10="","","-") | J12: =IF(Lists!$A$10="","","-") | K12: =IF(Lists!$A$10="","","-") | L12: =IF(Lists!$A$10="","","-")
A13: =IF(Lists!$A$11="","",Lists!$A$11) | B13: =IFERROR(IF(Lists!$A$11="","",INDEX(Database!$H:$H,MATCH(MAXIFS(Database!$A:$A,Database!$B:$B,Lists!$A$11),Database!$A:$A,0))),"") | C13: =IFERROR(IF(Lists!$A$11="","",IF(INDEX(Database!$J:$J,MATCH(MAXIFS(Database!$A:$A,Database!$B:$B,Lists!$A$11),Database!$A:$A,0))="Yes","Mixed-Use","Residential")),"") | D13: =IFERROR(IF(Lists!$A$11="","",N(INDEX(Database!$AA:$AA,MATCH(MAXIFS(Database!$A:$A,Database!$B:$B,Lists!$A$11),Database!$A:$A,0)))+N(INDEX(Database!$AF:$AF,MATCH(MAXIFS(Database!$A:$A,Database!$B:$B,Lists!$A$11),Database!$A:$A,0)))+N(INDEX(Database!$AK:$AK,MATCH(MAXIFS(Database!$A:$A,Database!$B:$B,Lists!$A$11),Database!$A:$A,0)))+N(INDEX(Database!$AP:$AP,MATCH(MAXIFS(Database!$A:$A,Database!$B:$B,Lists!$A$11),Database!$A:$A,0)))+N(INDEX(Database!$AU:$AU,MATCH(MAXIFS(Database!$A:$A,Database!$B:$B,Lists!$A$11),Database!$A:$A,0)))+N(INDEX(Database!$AZ:$AZ,MATCH(MAXIFS(Database!$A:$A,Database!$B:$B,Lists!$A$11),Database!$A:$A,0)))+N(INDEX(Database!$BE:$BE,MATCH(MAXIFS(Database!$A:$A,Database!$B:$B,Lists!$A$11),Database!$A:$A,0)))+N(INDEX(Database!$BJ:$BJ,MATCH(MAXIFS(Database!$A:$A,Database!$B:$B,Lists!$A$11),Database!$A:$A,0)))+N(INDEX(Database!$BO:$BO,MATCH(MAXIFS(Database!$A:$A,Database!$B:$B,Lists!$A$11),Database!$A:$A,0)))+N(INDEX(Database!$BT:$BT,MATCH(MAXIFS(Database!$A:$A,Database!$B:$B,Lists!$A$11),Database!$A:$A,0)))+N(INDEX(Database!$BY:$BY,MATCH(MAXIFS(Database!$A:$A,Database!$B:$B,Lists!$A$11),Database!$A:$A,0)))+N(INDEX(Database!$CD:$CD,MATCH(MAXIFS(Database!$A:$A,Database!$B:$B,Lists!$A$11),Database!$A:$A,0)))+N(INDEX(Database!$CI:$CI,MATCH(MAXIFS(Database!$A:$A,Database!$B:$B,Lists!$A$11),Database!$A:$A,0)))+N(INDEX(Database!$CN:$CN,MATCH(MAXIFS(Database!$A:$A,Database!$B:$B,Lists!$A$11),Database!$A:$A,0)))+N(INDEX(Database!$CS:$CS,MATCH(MAXIFS(Database!$A:$A,Database!$B:$B,Lists!$A$11),Database!$A:$A,0)))),"") | E13: =IFERROR(IF(Lists!$A$11="","",INDEX(Database!$M:$M,MATCH(MAXIFS(Database!$A:$A,Database!$B:$B,Lists!$A$11),Database!$A:$A,0))),"") | F13: =IF(Lists!$A$11="","","-") | G13: =IF(Lists!$A$11="","","-") | H13: =IF(Lists!$A$11="","","-") | I13: =IF(Lists!$A$11="","","-") | J13: =IF(Lists!$A$11="","","-") | K13: =IF(Lists!$A$11="","","-") | L13: =IF(Lists!$A$11="","","-")
A14: =IF(Lists!$A$12="","",Lists!$A$12) | B14: =IFERROR(IF(Lists!$A$12="","",INDEX(Database!$H:$H,MATCH(MAXIFS(Database!$A:$A,Database!$B:$B,Lists!$A$12),Database!$A:$A,0))),"") | C14: =IFERROR(IF(Lists!$A$12="","",IF(INDEX(Database!$J:$J,MATCH(MAXIFS(Database!$A:$A,Database!$B:$B,Lists!$A$12),Database!$A:$A,0))="Yes","Mixed-Use","Residential")),"") | D14: =IFERROR(IF(Lists!$A$12="","",N(INDEX(Database!$AA:$AA,MATCH(MAXIFS(Database!$A:$A,Database!$B:$B,Lists!$A$12),Database!$A:$A,0)))+N(INDEX(Database!$AF:$AF,MATCH(MAXIFS(Database!$A:$A,Database!$B:$B,Lists!$A$12),Database!$A:$A,0)))+N(INDEX(Database!$AK:$AK,MATCH(MAXIFS(Database!$A:$A,Database!$B:$B,Lists!$A$12),Database!$A:$A,0)))+N(INDEX(Database!$AP:$AP,MATCH(MAXIFS(Database!$A:$A,Database!$B:$B,Lists!$A$12),Database!$A:$A,0)))+N(INDEX(Database!$AU:$AU,MATCH(MAXIFS(Database!$A:$A,Database!$B:$B,Lists!$A$12),Database!$A:$A,0)))+N(INDEX(Database!$AZ:$AZ,MATCH(MAXIFS(Database!$A:$A,Database!$B:$B,Lists!$A$12),Database!$A:$A,0)))+N(INDEX(Database!$BE:$BE,MATCH(MAXIFS(Database!$A:$A,Database!$B:$B,Lists!$A$12),Database!$A:$A,0)))+N(INDEX(Database!$BJ:$BJ,MATCH(MAXIFS(Database!$A:$A,Database!$B:$B,Lists!$A$12),Database!$A:$A,0)))+N(INDEX(Database!$BO:$BO,MATCH(MAXIFS(Database!$A:$A,Database!$B:$B,Lists!$A$12),Database!$A:$A,0)))+N(INDEX(Database!$BT:$BT,MATCH(MAXIFS(Database!$A:$A,Database!$B:$B,Lists!$A$12),Database!$A:$A,0)))+N(INDEX(Database!$BY:$BY,MATCH(MAXIFS(Database!$A:$A,Database!$B:$B,Lists!$A$12),Database!$A:$A,0)))+N(INDEX(Database!$CD:$CD,MATCH(MAXIFS(Database!$A:$A,Database!$B:$B,Lists!$A$12),Database!$A:$A,0)))+N(INDEX(Database!$CI:$CI,MATCH(MAXIFS(Database!$A:$A,Database!$B:$B,Lists!$A$12),Database!$A:$A,0)))+N(INDEX(Database!$CN:$CN,MATCH(MAXIFS(Database!$A:$A,Database!$B:$B,Lists!$A$12),Database!$A:$A,0)))+N(INDEX(Database!$CS:$CS,MATCH(MAXIFS(Database!$A:$A,Database!$B:$B,Lists!$A$12),Database!$A:$A,0)))),"") | E14: =IFERROR(IF(Lists!$A$12="","",INDEX(Database!$M:$M,MATCH(MAXIFS(Database!$A:$A,Database!$B:$B,Lists!$A$12),Database!$A:$A,0))),"") | F14: =IF(Lists!$A$12="","","-") | G14: =IF(Lists!$A$12="","","-") | H14: =IF(Lists!$A$12="","","-") | I14: =IF(Lists!$A$12="","","-") | J14: =IF(Lists!$A$12="","","-") | K14: =IF(Lists!$A$12="","","-") | L14: =IF(Lists!$A$12="","","-")
