Workbook
Name Project_List: 'Lists'!$A$2:$A$101
Name Status_List: 'Lists'!$B$2:$B$3
Name UnitType_List: 'Lists'!$C$2:$C$5
Name RentBasis_List: 'Lists'!$D$2:$D$6
Name YesNo_List: 'Lists'!$E$2:$E$3
Name RentType_List: 'Lists'!$F$2:$F$3
Name CostCurve_List: 'Lists'!$G$2:$G$5
Name Growth_Defaults: 'Master Assumptions'!$B$5:$F$9
Name Growth_Rows: 'Master Assumptions'!$A$5:$A$9
Name SelectedProject: 'Cockpit'!$C$5
Name Console_Notes: 'Cockpit'!$C$7
Name Closing_Date_Cell: 'Cockpit'!$D$17
Name GSF_Cell: 'Cockpit'!$D$18
Name NSF_Cell: 'Cockpit'!$D$19
Name HasComm_Cell: 'Cockpit'!$D$26
Name CommSF_Cell: 'Cockpit'!$D$27
Name CommPSF_Cell: 'Cockpit'!$D$28
Name CommVac_Cell: 'Cockpit'!$D$31
Name CommOpEx_Cell: 'Cockpit'!$D$32
Name CommNOI_In: 'Cockpit'!$E$33
Name CommNOI_Cur: 'Cockpit'!$J$33
Name Units_Total: 'Cockpit'!$C$40
Name Units_Total_Cur: 'Cockpit'!$H$40
Name Blended_PUPM: 'Cockpit'!$E$40
Name Blended_PUPM_Cur: 'Cockpit'!$J$40
Name AvgSF_In: 'Cockpit'!$D$40
Name GPR_In: 'Cockpit'!$E$42
Name GPR_Cur: 'Cockpit'!$J$42
Name ERR_In: 'Cockpit'!$E$47
Name ERR_Cur: 'Cockpit'!$J$47
Name OtherInc_In: 'Cockpit'!$E$55
Name OtherInc_Cur: 'Cockpit'!$J$55
Name EGR_In: 'Cockpit'!$E$57
Name EGR_Cur: 'Cockpit'!$J$57
Name TotOpEx_In: 'Cockpit'!$E$70
Name TotOpEx_Cur: 'Cockpit'!$J$70
Name NOI_In: 'Cockpit'!$E$73
Name NOI_Cur: 'Cockpit'!$J$73
Name OpExRatio_In: 'Cockpit'!$E$74
Name TDC_In: 'Cockpit'!$E$90
Name TDC_Cur: 'Cockpit'!$J$90
Name MaxRecordsPerProject: 'Database'!$B$2
Name SelectedProjectDash: 'Project Dashboard'!$B$3

Sheet Read me
A1: Swerdlow Multi-Phase Asset Management & Underwriting Platform
A3: THE LOOP
A4: Pick a PROJECT (single selector, top of the Console) -> the GREEN 'Current' column shows the latest assumptions published to the database -> edit the BLUE input fields -> click PUBLISH. Publish validates, writes the blue values to the database as a new 'Current' record (prior Current -> Historical), and the green values refresh.
A6: ONE TAB FOR ALL INPUTS
A7: Every assumption lives on the Cockpit (Management Console) tab, laid out as a blue [INPUT] block (cols B-E) beside a green [Current] block (cols G-J) that mirrors the database. Black = calculated. The database is the single source of truth.
A9: TABS
A10: Read me | Cockpit (console) | Master Assumptions | Database | Portfolio Dashboard | Project Dashboard | Monthly CF. Hidden: Lists, Archive.
A12: ** ENABLING THE MACROS (.xlsx -> .xlsm) **
A13: Pure-Python tooling cannot author Excel's compiled VBA, so the macros ship as .bas files in ./vba. To enable:
A14: 1. Open in Excel -> Save As -> Excel Macro-Enabled Workbook (.xlsm).
A15: 2. Alt+F11 -> File > Import File... -> import each .bas in ./vba.
A16: 3. Assign Publish_Project to the red PUBLISH ASSUMPTIONS button, and Add_Project / Request_Support to their buttons.
... A20: Each Publish appends a record with User, Timestamp, Notes, and Status. Latest = Current; prior records for that project become Historical. FIFO cap (MaxRecordsPerProject, default 20) archives the oldest record per project to the hidden Archive tab (auditable).

Sheet Cockpit
B2: PUBLISH ASSUMPTIONS | D2: <- assign Publish_Project macro (placeholder button) | H2: Add Project | J2: Request Support
B4: MANAGEMENT CONSOLE | G4: CURRENT (latest published in database)
B5: Project | C5: RAD 1 | G5: Last published by | H5: =IFERROR(INDEX(Database!$E:$E,MATCH(MAXIFS(Database!$A:$A,Database!$B:$B,SelectedProject),Database!$A:$A,0)),"(none)")
B6: Record # | C6: =IFERROR(MAXIFS(Database!$A:$A,Database!$B:$B,SelectedProject),0) | G6: Published on | H6: =IFERROR(INDEX(Database!$D:$D,MATCH(MAXIFS(Database!$A:$A,Database!$B:$B,SelectedProject),Database!$A:$A,0)),"-")
B7: Notes (saved on Publish)
B9: KPIs (from working inputs)
B10: Total Units | C10: Total NSF | D10: EGR | E10: NOI | F10: OpEx Ratio | G10: NOI/Unit | H10: Total Dev Cost | I10: Cost/Unit | J10: Yield on Cost
B11: =Units_Total | C11: =NSF_Cell | D11: =EGR_In | E11: =NOI_In | F11: =OpExRatio_In | G11: =IFERROR(NOI_In/Units_Total,0) | H11: =TDC_In | I11: =IFERROR(TDC_In/Units_Total,0) | J11: =IFERROR(NOI_In/TDC_In,0)
B13: General Inputs | G13: Input | Current ->
B14: Phase No. | D14: 3 | G14: Phase No. | I14: =IFERROR(INDEX(Database!$G:$G,MATCH(MAXIFS(Database!$A:$A,Database!$B:$B,SelectedProject),Database!$A:$A,0)),"-")
B15: Project Name | D15: RAD 1 | F15: =IF(D15="","!","") | G15: Project Name | I15: =IFERROR(INDEX(Database!$H:$H,MATCH(MAXIFS(Database!$A:$A,Database!$B:$B,SelectedProject),Database!$A:$A,0)),"-")
B16: Land Size (Acres) | D16: 2 | G16: Land Size (Acres) | I16: =IFERROR(INDEX(Database!$I:$I,MATCH(MAXIFS(Database!$A:$A,Database!$B:$B,SelectedProject),Database!$A:$A,0)),"-")
B17: Closing Date | D17: 46204 | F17: =IF(N(D17)=0,"!","") | G17: Closing Date | I17: =IFERROR(INDEX(Database!$J:$J,MATCH(MAXIFS(Database!$A:$A,Database!$B:$B,SelectedProject),Database!$A:$A,0)),"-")
B18: Gross Building Area (GSF) | D18: 240000 | F18: =IF(N(D18)=0,"!","") | G18: Gross Building Area (GSF) | I18: =IFERROR(INDEX(Database!$K:$K,MATCH(MAXIFS(Database!$A:$A,Database!$B:$B,SelectedProject),Database!$A:$A,0)),"-")
B19: Net Rentable Area (NSF) | D19: 200000 | G19: Net Rentable Area (NSF) | I19: =IFERROR(INDEX(Database!$L:$L,MATCH(MAXIFS(Database!$A:$A,Database!$B:$B,SelectedProject),Database!$A:$A,0)),"-")
B20: Key Dates | G20: Input | Current ->
B21: Construction Start (month offset) | D21: 2 | E21: =EDATE(Closing_Date_Cell,D21) | G21: Construction Start | I21: =IFERROR(INDEX(Database!$M:$M,MATCH(MAXIFS(Database!$A:$A,Database!$B:$B,SelectedProject),Database!$A:$A,0)),"-") | J21: =IFERROR(EDATE(Closing_Date_Cell,I21),"-")
B22: Initial Occupancy (month offset) | D22: 14 | E22: =EDATE(Closing_Date_Cell,D22) | G22: Initial Occupancy | I22: =IFERROR(INDEX(Database!$N:$N,MATCH(MAXIFS(Database!$A:$A,Database!$B:$B,SelectedProject),Database!$A:$A,0)),"-") | J22: =IFERROR(EDATE(Closing_Date_Cell,I22),"-")
B23: Construction End (month offset) | D23: 20 | E23: =EDATE(Closing_Date_Cell,D23) | G23: Construction End | I23: =IFERROR(INDEX(Database!$O:$O,MATCH(MAXIFS(Database!$A:$A,Database!$B:$B,SelectedProject),Database!$A:$A,0)),"-") | J23: =IFERROR(EDATE(Closing_Date_Cell,I23),"-")
B24: Stabilization (month offset) | D24: 30 | E24: =EDATE(Closing_Date_Cell,D24) | G24: Stabilization | I24: =IFERROR(INDEX(Database!$P:$P,MATCH(MAXIFS(Database!$A:$A,Database!$B:$B,SelectedProject),Database!$A:$A,0)),"-") | J24: =IFERROR(EDATE(Closing_Date_Cell,I24),"-")
B25: Commercial Assumptions | G25: Input | Current ->
B26: Has Commercial? | D26: No | G26: Has Commercial? | I26: =IFERROR(INDEX(Database!$Q:$Q,MATCH(MAXIFS(Database!$A:$A,Database!$B:$B,SelectedProject),Database!$A:$A,0)),"-")
B27: Commercial Leasable SF | D27: 0 | G27: Commercial Leasable SF | I27: =IFERROR(INDEX(Database!$R:$R,MATCH(MAXIFS(Database!$A:$A,Database!$B:$B,SelectedProject),Database!$A:$A,0)),"-")
B28: Annual Rent PSF | D28: 30 | G28: Annual Rent PSF | I28: =IFERROR(INDEX(Database!$S:$S,MATCH(MAXIFS(Database!$A:$A,Database!$B:$B,SelectedProject),Database!$A:$A,0)),"-")
B29: Escalation | D29: 0.03 | G29: Escalation | I29: =IFERROR(INDEX(Database!$T:$T,MATCH(MAXIFS(Database!$A:$A,Database!$B:$B,SelectedProject),Database!$A:$A,0)),"-")
B30: Abatement (months) | D30: 0 | G30: Abatement (months) | I30: =IFERROR(INDEX(Database!$U:$U,MATCH(MAXIFS(Database!$A:$A,Database!$B:$B,SelectedProject),Database!$A:$A,0)),"-")
B31: General Vacancy % | D31: 0.07 | G31: General Vacancy % | I31: =IFERROR(INDEX(Database!$V:$V,MATCH(MAXIFS(Database!$A:$A,Database!$B:$B,SelectedProject),Database!$A:$A,0)),"-")
B32: Operating Expenses $/SF | D32: 6.75 | G32: Operating Expenses $/SF | I32: =IFERROR(INDEX(Database!$W:$W,MATCH(MAXIFS(Database!$A:$A,Database!$B:$B,SelectedProject),Database!$A:$A,0)),"-")
B33: Stabilized Commercial NOI | E33: =IF(HasComm_Cell="Yes",CommSF_Cell*CommPSF_Cell*(1-CommVac_Cell)-CommSF_Cell*CommOpEx_Cell,0) | G33: Stabilized Commercial NOI | J33: =IFERROR(IF(INDEX(Database!$Q:$Q,MATCH(MAXIFS(Database!$A:$A,Database!$B:$B,SelectedProject),Database!$A:$A,0))="Yes",INDEX(Database!$R:$R,MATCH(MAXIFS(Database!$A:$A,Database!$B:$B,SelectedProject),Database!$A:$A,0))*INDEX(Database!$S:$S,MATCH(MAXIFS(Database!$A:$A,Database!$B:$B,SelectedProject),Database!$A:$A,0))*(1-INDEX(Database!$V:$V,MATCH(MAXIFS(Database!$A:$A,Database!$B:$B,SelectedProject),Database!$A:$A,0)))-INDEX(Database!$R:$R,MATCH(MAXIFS(Database!$A:$A,Database!$B:$B,SelectedProject),Database!$A:$A,0))*INDEX(Database!$W:$W,MATCH(MAXIFS(Database!$A:$A,Database!$B:$B,SelectedProject),Database!$A:$A,0)),0),0)
B34: Multifamily - Unit Mix & Rental Revenue (Exhibit A/C) | G34: Input | Current ->
B35: Unit Type | C35: Count | D35: Avg SF | E35: $ PUPM | G35: Unit Type | H35: Count | I35: Avg SF | J35: $ PUPM
B36: Studio | C36: 1 | D36: 2000 | E36: 2000 | G36: Studio | H36: =IFERROR(INDEX(Database!$Y:$Y,MATCH(MAXIFS(Database!$A:$A,Database!$B:$B,SelectedProject),Database!$A:$A,0)),"-") | I36: =IFERROR(INDEX(Database!$Z:$Z,MATCH(MAXIFS(Database!$A:$A,Database!$B:$B,SelectedProject),Database!$A:$A,0)),"-") | J36: =IFERROR(INDEX(Database!$AA:$AA,MATCH(MAXIFS(Database!$A:$A,Database!$B:$B,SelectedProject),Database!$A:$A,0)),"-")
B37: 1 Bedroom | C37: 1 | D37: 2000 | E37: 1500 | G37: 1 Bedroom | H37: =IFERROR(INDEX(Database!$AC:$AC,MATCH(MAXIFS(Database!$A:$A,Database!$B:$B,SelectedProject),Database!$A:$A,0)),"-") | I37: =IFERROR(INDEX(Database!$AD:$AD,MATCH(MAXIFS(Database!$A:$A,Database!$B:$B,SelectedProject),Database!$A:$A,0)),"-") | J37: =IFERROR(INDEX(Database!$AE:$AE,MATCH(MAXIFS(Database!$A:$A,Database!$B:$B,SelectedProject),Database!$A:$A,0)),"-")
B38: 2 Bedroom | C38: 1 | D38: 2000 | E38: 1000 | G38: 2 Bedroom | H38: =IFERROR(INDEX(Database!$AG:$AG,MATCH(MAXIFS(Database!$A:$A,Database!$B:$B,SelectedProject),Database!$A:$A,0)),"-") | I38: =IFERROR(INDEX(Database!$AH:$AH,MATCH(MAXIFS(Database!$A:$A,Database!$B:$B,SelectedProject),Database!$A:$A,0)),"-") | J38: =IFERROR(INDEX(Database!$AI:$AI,MATCH(MAXIFS(Database!$A:$A,Database!$B:$B,SelectedProject),Database!$A:$A,0)),"-")
B39: 3 Bedroom | C39: 1 | D39: 2000 | E39: 1000 | G39: 3 Bedroom | H39: =IFERROR(INDEX(Database!$AK:$AK,MATCH(MAXIFS(Database!$A:$A,Database!$B:$B,SelectedProject),Database!$A:$A,0)),"-") | I39: =IFERROR(INDEX(Database!$AL:$AL,MATCH(MAXIFS(Database!$A:$A,Database!$B:$B,SelectedProject),Database!$A:$A,0)),"-") | J39: =IFERROR(INDEX(Database!$AM:$AM,MATCH(MAXIFS(Database!$A:$A,Database!$B:$B,SelectedProject),Database!$A:$A,0)),"-")
B40: Total / Blended | C40: =SUM(C36:C39) | D40: =IFERROR(SUMPRODUCT(D36:D39,C36:C39)/C40,0) | E40: =IFERROR(SUMPRODUCT(E36:E39,C36:C39)/C40,0) | G40: Total / Blended | H40: =SUM(H36:H39) | I40: =IFERROR(SUMPRODUCT(I36:I39,H36:H39)/H40,0) | J40: =IFERROR(SUMPRODUCT(J36:J39,H36:H39)/H40,0)
B42: Gross Potential Rent | E42: =Blended_PUPM*Units_Total*12 | G42: Gross Potential Rent | J42: =Blended_PUPM_Cur*Units_Total_Cur*12
B43: Vacancy | D43: 0.05 | E43: =-GPR_In*D43 | G43: Vacancy | I43: =IFERROR(INDEX(Database!$AN:$AN,MATCH(MAXIFS(Database!$A:$A,Database!$B:$B,SelectedProject),Database!$A:$A,0)),"-") | J43: =-GPR_Cur*I43
B44: Concessions | D44: 0 | E44: =-GPR_In*D44 | G44: Concessions | I44: =IFERROR(INDEX(Database!$AO:$AO,MATCH(MAXIFS(Database!$A:$A,Database!$B:$B,SelectedProject),Database!$A:$A,0)),"-") | J44: =-GPR_Cur*I44
B45: Model | D45: 0 | E45: =-GPR_In*D45 | G45: Model | I45: =IFERROR(INDEX(Database!$AP:$AP,MATCH(MAXIFS(Database!$A:$A,Database!$B:$B,SelectedProject),Database!$A:$A,0)),"-") | J45: =-GPR_Cur*I45
...

Sheet Master Assumptions
A1: MASTER ASSUMPTIONS - program-wide growth defaults (Exhibit E)
A2: Per-phase overrides live on the Console. Year 5 = Year 5+.
A4: Category | B4: Year 1 | C4: Year 2 | D4: Year 3 | E4: Year 4 | F4: Year 5
A5: Market Rents | B5: 0.03 | C5: 0.03 | D5: 0.03 | E5: 0.03 | F5: 0.03
A6: Affordable Rents | B6: 0.025 | C6: 0.025 | D6: 0.025 | E6: 0.025 | F6: 0.025
A7: Retail Rents | B7: 0.025 | C7: 0.025 | D7: 0.025 | E7: 0.025 | F7: 0.025
A8: Other Income | B8: 0.025 | C8: 0.025 | D8: 0.025 | E8: 0.025 | F8: 0.025
A9: Operating Expenses | B9: 0.03 | C9: 0.03 | D9: 0.03 | E9: 0.03 | F9: 0.03

Sheet Database
A1: DATABASE - relational system of record (one row = one published record). Do not edit by hand.
A2: MaxRecordsPerProject | B2: 20 | C2: FIFO cap; oldest record per Project is archived on overflow. Status: Current vs Historical.
A4: RecordID | B4: Project | C4: Status | D4: Timestamp | E4: UpdatedBy | F4: Notes | G4: PhaseNo | H4: ProjectName | I4: LandAcres | J4: ClosingDate | K4: GSF | L4: NSF | M4: off_ConstStart | N4: off_InitOcc | O4: off_ConstEnd | P4: off_Stab | Q4: HasCommercial | R4: CommSF | S4: CommRentPSF | T4: CommEscalation | U4: CommAbatement | V4: CommVacancy | W4: CommOpExPSF | X4: UM1_Type | Y4: UM1_Count | Z4: UM1_AvgSF | AA4: UM1_PUPM | AB4: UM2_Type | AC4: UM2_Count | AD4: UM2_AvgSF | AE4: UM2_PUPM | AF4: UM3_Type | AG4: UM3_Count | AH4: UM3_AvgSF | AI4: UM3_PUPM | AJ4: UM4_Type | AK4: UM4_Count | AL4: UM4_AvgSF | AM4: UM4_PUPM | AN4: ResVacancy | AO4: ResConcessions | AP4: ResModel | AQ4: ResCollLoss | AR4: OI1_Name | AS4: OI1_PUPM | AT4: OI2_Name | AU4: OI2_PUPM | AV4: OI3_Name | AW4: OI3_PUPM | AX4: OI4_Name | AY4: OI4_PUPM | AZ4: OI5_Name | BA4: OI5_PUPM | BB4: OpEx_Payroll | BC4: OpEx_Marketing | BD4: OpEx_Admin | BE4: OpEx_ProfFees | BF4: OpEx_RM | BG4: OpEx_Utilities | BH4: OpEx_Insurance | BI4: OpEx_RETaxes | BJ4: OpEx_MgmtFeePct | BK4: Bud_Land | BL4: Bud_Shell | BM4: Bud_Sitework | BN4: Bud_Parking | BO4: Bud_FFE | BP4: Bud_GCFee | BQ4: Bud_AE | BR4: Bud_Permits | BS4: Bud_Legal | BT4: Bud_Mktg | BU4: Bud_DevFee | BV4: Bud_TaxIns
A5: 1 | B5: RAD 1 | C5: Current | D5: 46196 | E5: seed | F5: initial seed record | G5: =Cockpit!$D$14 | H5: =Cockpit!$D$15 | I5: =Cockpit!$D$16 | J5: =Cockpit!$D$17 | K5: =Cockpit!$D$18 | L5: =Cockpit!$D$19 | M5: =Cockpit!$D$21 | N5: =Cockpit!$D$22 | O5: =Cockpit!$D$23 | P5: =Cockpit!$D$24 | Q5: =Cockpit!$D$26 | R5: =Cockpit!$D$27 | S5: =Cockpit!$D$28 | T5: =Cockpit!$D$29 | U5: =Cockpit!$D$30 | V5: =Cockpit!$D$31 | W5: =Cockpit!$D$32 | X5: =Cockpit!$B$36 | Y5: =Cockpit!$C$36 | Z5: =Cockpit!$D$36 | AA5: =Cockpit!$E$36 | AB5: =Cockpit!$B$37 | AC5: =Cockpit!$C$37 | AD5: =Cockpit!$D$37 | AE5: =Cockpit!$E$37 | AF5: =Cockpit!$B$38 | AG5: =Cockpit!$C$38 | AH5: =Cockpit!$D$38 | AI5: =Cockpit!$E$38 | AJ5: =Cockpit!$B$39 | AK5: =Cockpit!$C$39 | AL5: =Cockpit!$D$39 | AM5: =Cockpit!$E$39 | AN5: =Cockpit!$D$43 | AO5: =Cockpit!$D$44 | AP5: =Cockpit!$D$45 | AQ5: =Cockpit!$D$46 | AR5: =Cockpit!$B$50 | AS5: =Cockpit!$D$50 | AT5: =Cockpit!$B$51 | AU5: =Cockpit!$D$51 | AV5: =Cockpit!$B$52 | AW5: =Cockpit!$D$52 | AX5: =Cockpit!$B$53 | AY5: =Cockpit!$D$53 | AZ5: =Cockpit!$B$54 | BA5: =Cockpit!$D$54 | BB5: =Cockpit!$D$61 | BC5: =Cockpit!$D$62 | BD5: =Cockpit!$D$63 | BE5: =Cockpit!$D$64 | BF5: =Cockpit!$D$65 | BG5: =Cockpit!$D$66 | BH5: =Cockpit!$D$67 | BI5: =Cockpit!$D$68 | BJ5: =Cockpit!$D$69 | BK5: =Cockpit!$D$78 | BL5: =Cockpit!$D$79 | BM5: =Cockpit!$D$80 | BN5: =Cockpit!$D$81 | BO5: =Cockpit!$D$82 | BP5: =Cockpit!$D$83 | BQ5: =Cockpit!$D$84 | BR5: =Cockpit!$D$85 | BS5: =Cockpit!$D$86 | BT5: =Cockpit!$D$87 | BU5: =Cockpit!$D$88 | BV5: =Cockpit!$D$89
A6: 2 | B6: RAD 2 | C6: Current | D6: 46196 | E6: seed | F6: initial seed record
A7: 3 | B7: Live Local A | C7: Current | D7: 46196 | E7: seed | F7: initial seed record

Sheet Portfolio Dashboard
A1: PORTFOLIO DASHBOARD - all projects (latest published record), read-only
A3: Project | B3: Phase No. | C3: Units | D3: NSF | E3: EGR | F3: NOI | G3: OpEx Ratio | H3: Total Dev Cost | I3: Cost/Unit | J3: Yield on Cost
A4: =IF(Lists!$A$2="","",Lists!$A$2) | B4: =IFERROR(IF(Lists!$A$2="","",INDEX(Database!$G:$G,MATCH(MAXIFS(Database!$A:$A,Database!$B:$B,Lists!$A$2),Database!$A:$A,0))),"") | C4: =IFERROR(IF(Lists!$A$2="","",N(INDEX(Database!$Y:$Y,MATCH(MAXIFS(Database!$A:$A,Database!$B:$B,Lists!$A$2),Database!$A:$A,0)))+N(INDEX(Database!$AC:$AC,MATCH(MAXIFS(Database!$A:$A,Database!$B:$B,Lists!$A$2),Database!$A:$A,0)))+N(INDEX(Database!$AG:$AG,MATCH(MAXIFS(Database!$A:$A,Database!$B:$B,Lists!$A$2),Database!$A:$A,0)))+N(INDEX(Database!$AK:$AK,MATCH(MAXIFS(Database!$A:$A,Database!$B:$B,Lists!$A$2),Database!$A:$A,0)))),"") | D4: =IFERROR(IF(Lists!$A$2="","",INDEX(Database!$L:$L,MATCH(MAXIFS(Database!$A:$A,Database!$B:$B,Lists!$A$2),Database!$A:$A,0))),"") | E4: =IF(Lists!$A$2="","","-") | F4: =IF(Lists!$A$2="","","-") | G4: =IF(Lists!$A$2="","","-") | H4: =IF(Lists!$A$2="","","-") | I4: =IF(Lists!$A$2="","","-") | J4: =IF(Lists!$A$2="","","-")
A5: =IF(Lists!$A$3="","",Lists!$A$3) | B5: =IFERROR(IF(Lists!$A$3="","",INDEX(Database!$G:$G,MATCH(MAXIFS(Database!$A:$A,Database!$B:$B,Lists!$A$3),Database!$A:$A,0))),"") | C5: =IFERROR(IF(Lists!$A$3="","",N(INDEX(Database!$Y:$Y,MATCH(MAXIFS(Database!$A:$A,Database!$B:$B,Lists!$A$3),Database!$A:$A,0)))+N(INDEX(Database!$AC:$AC,MATCH(MAXIFS(Database!$A:$A,Database!$B:$B,Lists!$A$3),Database!$A:$A,0)))+N(INDEX(Database!$AG:$AG,MATCH(MAXIFS(Database!$A:$A,Database!$B:$B,Lists!$A$3),Database!$A:$A,0)))+N(INDEX(Database!$AK:$AK,MATCH(MAXIFS(Database!$A:$A,Database!$B:$B,Lists!$A$3),Database!$A:$A,0)))),"") | D5: =IFERROR(IF(Lists!$A$3="","",INDEX(Database!$L:$L,MATCH(MAXIFS(Database!$A:$A,Database!$B:$B,Lists!$A$3),Database!$A:$A,0))),"") | E5: =IF(Lists!$A$3="","","-") | F5: =IF(Lists!$A$3="","","-") | G5: =IF(Lists!$A$3="","","-") | H5: =IF(Lists!$A$3="","","-") | I5: =IF(Lists!$A$3="","","-") | J5: =IF(Lists!$A$3="","","-")
A6: =IF(Lists!$A$4="","",Lists!$A$4) | B6: =IFERROR(IF(Lists!$A$4="","",INDEX(Database!$G:$G,MATCH(MAXIFS(Database!$A:$A,Database!$B:$B,Lists!$A$4),Database!$A:$A,0))),"") | C6: =IFERROR(IF(Lists!$A$4="","",N(INDEX(Database!$Y:$Y,MATCH(MAXIFS(Database!$A:$A,Database!$B:$B,Lists!$A$4),Database!$A:$A,0)))+N(INDEX(Database!$AC:$AC,MATCH(MAXIFS(Database!$A:$A,Database!$B:$B,Lists!$A$4),Database!$A:$A,0)))+N(INDEX(Database!$AG:$AG,MATCH(MAXIFS(Database!$A:$A,Database!$B:$B,Lists!$A$4),Database!$A:$A,0)))+N(INDEX(Database!$AK:$AK,MATCH(MAXIFS(Database!$A:$A,Database!$B:$B,Lists!$A$4),Database!$A:$A,0)))),"") | D6: =IFERROR(IF(Lists!$A$4="","",INDEX(Database!$L:$L,MATCH(MAXIFS(Database!$A:$A,Database!$B:$B,Lists!$A$4),Database!$A:$A,0))),"") | E6: =IF(Lists!$A$4="","","-") | F6: =IF(Lists!$A$4="","","-") | G6: =IF(Lists!$A$4="","","-") | H6: =IF(Lists!$A$4="","","-") | I6: =IF(Lists!$A$4="","","-") | J6: =IF(Lists!$A$4="","","-")
A7: =IF(Lists!$A$5="","",Lists!$A$5) | B7: =IFERROR(IF(Lists!$A$5="","",INDEX(Database!$G:$G,MATCH(MAXIFS(Database!$A:$A,Database!$B:$B,Lists!$A$5),Database!$A:$A,0))),"") | C7: =IFERROR(IF(Lists!$A$5="","",N(INDEX(Database!$Y:$Y,MATCH(MAXIFS(Database!$A:$A,Database!$B:$B,Lists!$A$5),Database!$A:$A,0)))+N(INDEX(Database!$AC:$AC,MATCH(MAXIFS(Database!$A:$A,Database!$B:$B,Lists!$A$5),Database!$A:$A,0)))+N(INDEX(Database!$AG:$AG,MATCH(MAXIFS(Database!$A:$A,Database!$B:$B,Lists!$A$5),Database!$A:$A,0)))+N(INDEX(Database!$AK:$AK,MATCH(MAXIFS(Database!$A:$A,Database!$B:$B,Lists!$A$5),Database!$A:$A,0)))),"") | D7: =IFERROR(IF(Lists!$A$5="","",INDEX(Database!$L:$L,MATCH(MAXIFS(Database!$A:$A,Database!$B:$B,Lists!$A$5),Database!$A:$A,0))),"") | E7: =IF(Lists!$A$5="","","-") | F7: =IF(Lists!$A$5="","","-") | G7: =IF(Lists!$A$5="","","-") | H7: =IF(Lists!$A$5="","","-") | I7: =IF(Lists!$A$5="","","-") | J7: =IF(Lists!$A$5="","","-")
A8: =IF(Lists!$A$6="","",Lists!$A$6) | B8: =IFERROR(IF(Lists!$A$6="","",INDEX(Database!$G:$G,MATCH(MAXIFS(Database!$A:$A,Database!$B:$B,Lists!$A$6),Database!$A:$A,0))),"") | C8: =IFERROR(IF(Lists!$A$6="","",N(INDEX(Database!$Y:$Y,MATCH(MAXIFS(Database!$A:$A,Database!$B:$B,Lists!$A$6),Database!$A:$A,0)))+N(INDEX(Database!$AC:$AC,MATCH(MAXIFS(Database!$A:$A,Database!$B:$B,Lists!$A$6),Database!$A:$A,0)))+N(INDEX(Database!$AG:$AG,MATCH(MAXIFS(Database!$A:$A,Database!$B:$B,Lists!$A$6),Database!$A:$A,0)))+N(INDEX(Database!$AK:$AK,MATCH(MAXIFS(Database!$A:$A,Database!$B:$B,Lists!$A$6),Database!$A:$A,0)))),"") | D8: =IFERROR(IF(Lists!$A$6="","",INDEX(Database!$L:$L,MATCH(MAXIFS(Database!$A:$A,Database!$B:$B,Lists!$A$6),Database!$A:$A,0))),"") | E8: =IF(Lists!$A$6="","","-") | F8: =IF(Lists!$A$6="","","-") | G8: =IF(Lists!$A$6="","","-") | H8: =IF(Lists!$A$6="","","-") | I8: =IF(Lists!$A$6="","","-") | J8: =IF(Lists!$A$6="","","-")
A9: =IF(Lists!$A$7="","",Lists!$A$7) | B9: =IFERROR(IF(Lists!$A$7="","",INDEX(Database!$G:$G,MATCH(MAXIFS(Database!$A:$A,Database!$B:$B,Lists!$A$7),Database!$A:$A,0))),"") | C9: =IFERROR(IF(Lists!$A$7="","",N(INDEX(Database!$Y:$Y,MATCH(MAXIFS(Database!$A:$A,Database!$B:$B,Lists!$A$7),Database!$A:$A,0)))+N(INDEX(Database!$AC:$AC,MATCH(MAXIFS(Database!$A:$A,Database!$B:$B,Lists!$A$7),Database!$A:$A,0)))+N(INDEX(Database!$AG:$AG,MATCH(MAXIFS(Database!$A:$A,Database!$B:$B,Lists!$A$7),Database!$A:$A,0)))+N(INDEX(Database!$AK:$AK,MATCH(MAXIFS(Database!$A:$A,Database!$B:$B,Lists!$A$7),Database!$A:$A,0)))),"") | D9: =IFERROR(IF(Lists!$A$7="","",INDEX(Database!$L:$L,MATCH(MAXIFS(Database!$A:$A,Database!$B:$B,Lists!$A$7),Database!$A:$A,0))),"") | E9: =IF(Lists!$A$7="","","-") | F9: =IF(Lists!$A$7="","","-") | G9: =IF(Lists!$A$7="","","-") | H9: =IF(Lists!$A$7="","","-") | I9: =IF(Lists!$A$7="","","-") | J9: =IF(Lists!$A$7="","","-")
A10: =IF(Lists!$A$8="","",Lists!$A$8) | B10: =IFERROR(IF(Lists!$A$8="","",INDEX(Database!$G:$G,MATCH(MAXIFS(Database!$A:$A,Database!$B:$B,Lists!$A$8),Database!$A:$A,0))),"") | C10: =IFERROR(IF(Lists!$A$8="","",N(INDEX(Database!$Y:$Y,MATCH(MAXIFS(Database!$A:$A,Database!$B:$B,Lists!$A$8),Database!$A:$A,0)))+N(INDEX(Database!$AC:$AC,MATCH(MAXIFS(Database!$A:$A,Database!$B:$B,Lists!$A$8),Database!$A:$A,0)))+N(INDEX(Database!$AG:$AG,MATCH(MAXIFS(Database!$A:$A,Database!$B:$B,Lists!$A$8),Database!$A:$A,0)))+N(INDEX(Database!$AK:$AK,MATCH(MAXIFS(Database!$A:$A,Database!$B:$B,Lists!$A$8),Database!$A:$A,0)))),"") | D10: =IFERROR(IF(Lists!$A$8="","",INDEX(Database!$L:$L,MATCH(MAXIFS(Database!$A:$A,Database!$B:$B,Lists!$A$8),Database!$A:$A,0))),"") | E10: =IF(Lists!$A$8="","","-") | F10: =IF(Lists!$A$8="","","-") | G10: =IF(Lists!$A$8="","","-") | H10: =IF(Lists!$A$8="","","-") | I10: =IF(Lists!$A$8="","","-") | J10: =IF(Lists!$A$8="","","-")
A11: =IF(Lists!$A$9="","",Lists!$A$9) | B11: =IFERROR(IF(Lists!$A$9="","",INDEX(Database!$G:$G,MATCH(MAXIFS(Database!$A:$A,Database!$B:$B,Lists!$A$9),Database!$A:$A,0))),"") | C11: =IFERROR(IF(Lists!$A$9="","",N(INDEX(Database!$Y:$Y,MATCH(MAXIFS(Database!$A:$A,Database!$B:$B,Lists!$A$9),Database!$A:$A,0)))+N(INDEX(Database!$AC:$AC,MATCH(MAXIFS(Database!$A:$A,Database!$B:$B,Lists!$A$9),Database!$A:$A,0)))+N(INDEX(Database!$AG:$AG,MATCH(MAXIFS(Database!$A:$A,Database!$B:$B,Lists!$A$9),Database!$A:$A,0)))+N(INDEX(Database!$AK:$AK,MATCH(MAXIFS(Database!$A:$A,Database!$B:$B,Lists!$A$9),Database!$A:$A,0)))),"") | D11: =IFERROR(IF(Lists!$A$9="","",INDEX(Database!$L:$L,MATCH(MAXIFS(Database!$A:$A,Database!$B:$B,Lists!$A$9),Database!$A:$A,0))),"") | E11: =IF(Lists!$A$9="","","-") | F11: =IF(Lists!$A$9="","","-") | G11: =IF(Lists!$A$9="","","-") | H11: =IF(Lists!$A$9="","","-") | I11: =IF(Lists!$A$9="","","-") | J11: =IF(Lists!$A$9="","","-")
A12: =IF(Lists!$A$10="","",Lists!$A$10) | B12: =IFERROR(IF(Lists!$A$10="","",INDEX(Database!$G:$G,MATCH(MAXIFS(Database!$A:$A,Database!$B:$B,Lists!$A$10),Database!$A:$A,0))),"") | C12: =IFERROR(IF(Lists!$A$10="","",N(INDEX(Database!$Y:$Y,MATCH(MAXIFS(Database!$A:$A,Database!$B:$B,Lists!$A$10),Database!$A:$A,0)))+N(INDEX(Database!$AC:$AC,MATCH(MAXIFS(Database!$A:$A,Database!$B:$B,Lists!$A$10),Database!$A:$A,0)))+N(INDEX(Database!$AG:$AG,MATCH(MAXIFS(Database!$A:$A,Database!$B:$B,Lists!$A$10),Database!$A:$A,0)))+N(INDEX(Database!$AK:$AK,MATCH(MAXIFS(Database!$A:$A,Database!$B:$B,Lists!$A$10),Database!$A:$A,0)))),"") | D12: =IFERROR(IF(Lists!$A$10="","",INDEX(Database!$L:$L,MATCH(MAXIFS(Database!$A:$A,Database!$B:$B,Lists!$A$10),Database!$A:$A,0))),"") | E12: =IF(Lists!$A$10="","","-") | F12: =IF(Lists!$A$10="","","-") | G12: =IF(Lists!$A$10="","","-") | H12: =IF(Lists!$A$10="","","-") | I12: =IF(Lists!$A$10="","","-") | J12: =IF(Lists!$A$10="","","-")
A13: =IF(Lists!$A$11="","",Lists!$A$11) | B13: =IFERROR(IF(Lists!$A$11="","",INDEX(Database!$G:$G,MATCH(MAXIFS(Database!$A:$A,Database!$B:$B,Lists!$A$11),Database!$A:$A,0))),"") | C13: =IFERROR(IF(Lists!$A$11="","",N(INDEX(Database!$Y:$Y,MATCH(MAXIFS(Database!$A:$A,Database!$B:$B,Lists!$A$11),Database!$A:$A,0)))+N(INDEX(Database!$AC:$AC,MATCH(MAXIFS(Database!$A:$A,Database!$B:$B,Lists!$A$11),Database!$A:$A,0)))+N(INDEX(Database!$AG:$AG,MATCH(MAXIFS(Database!$A:$A,Database!$B:$B,Lists!$A$11),Database!$A:$A,0)))+N(INDEX(Database!$AK:$AK,MATCH(MAXIFS(Database!$A:$A,Database!$B:$B,Lists!$A$11),Database!$A:$A,0)))),"") | D13: =IFERROR(IF(Lists!$A$11="","",INDEX(Database!$L:$L,MATCH(MAXIFS(Database!$A:$A,Database!$B:$B,Lists!$A$11),Database!$A:$A,0))),"") | E13: =IF(Lists!$A$11="","","-") | F13: =IF(Lists!$A$11="","","-") | G13: =IF(Lists!$A$11="","","-") | H13: =IF(Lists!$A$11="","","-") | I13: =IF(Lists!$A$11="","","-") | J13: =IF(Lists!$A$11="","","-")
A14: =IF(Lists!$A$12="","",Lists!$A$12) | B14: =IFERROR(IF(Lists!$A$12="","",INDEX(Database!$G:$G,MATCH(MAXIFS(Database!$A:$A,Database!$B:$B,Lists!$A$12),Database!$A:$A,0))),"") | C14: =IFERROR(IF(Lists!$A$12="","",N(INDEX(Database!$Y:$Y,MATCH(MAXIFS(Database!$A:$A,Database!$B:$B,Lists!$A$12),Database!$A:$A,0)))+N(INDEX(Database!$AC:$AC,MATCH(MAXIFS(Database!$A:$A,Database!$B:$B,Lists!$A$12),Database!$A:$A,0)))+N(INDEX(Database!$AG:$AG,MATCH(MAXIFS(Database!$A:$A,Database!$B:$B,Lists!$A$12),Database!$A:$A,0)))+N(INDEX(Database!$AK:$AK,MATCH(MAXIFS(Database!$A:$A,Database!$B:$B,Lists!$A$12),Database!$A:$A,0)))),"") | D14: =IFERROR(IF(Lists!$A$12="","",INDEX(Database!$L:$L,MATCH(MAXIFS(Database!$A:$A,Database!$B:$B,Lists!$A$12),Database!$A:$A,0))),"") | E14: =IF(Lists!$A$12="","","-") | F14: =IF(Lists!$A$12="","","-") | G14: =IF(Lists!$A$12="","","-") | H14: =IF(Lists!$A$12="","","-") | I14: =IF(Lists!$A$12="","","-") | J14: =IF(Lists!$A$12="","","-")
A15: =IF(Lists!$A$13="","",Lists!$A$13) | B15: =IFERROR(IF(Lists!$A$13="","",INDEX(Database!$G:$G,MATCH(MAXIFS(Database!$A:$A,Database!$B:$B,Lists!$A$13),Database!$A:$A,0))),"") | C15: =IFERROR(IF(Lists!$A$13="","",N(INDEX(Database!$Y:$Y,MATCH(MAXIFS(Database!$A:$A,Database!$B:$B,Lists!$A$13),Database!$A:$A,0)))+N(INDEX(Database!$AC:$AC,MATCH(MAXIFS(Database!$A:$A,Database!$B:$B,Lists!$A$13),Database!$A:$A,0)))+N(INDEX(Database!$AG:$AG,MATCH(MAXIFS(Database!$A:$A,Database!$B:$B,Lists!$A$13),Database!$A:$A,0)))+N(INDEX(Database!$AK:$AK,MATCH(MAXIFS(Database!$A:$A,Database!$B:$B,Lists!$A$13),Database!$A:$A,0)))),"") | D15: =IFERROR(IF(Lists!$A$13="","",INDEX(Database!$L:$L,MATCH(MAXIFS(Database!$A:$A,Database!$B:$B,Lists!$A$13),Database!$A:$A,0))),"") | E15: =IF(Lists!$A$13="","","-") | F15: =IF(Lists!$A$13="","","-") | G15: =IF(Lists!$A$13="","","-") | H15: =IF(Lists!$A$13="","","-") | I15: =IF(Lists!$A$13="","","-") | J15: =IF(Lists!$A$13="","","-")
A16: =IF(Lists!$A$14="","",Lists!$A$14) | B16: =IFERROR(IF(Lists!$A$14="","",INDEX(Database!$G:$G,MATCH(MAXIFS(Database!$A:$A,Database!$B:$B,Lists!$A$14),Database!$A:$A,0))),"") | C16: =IFERROR(IF(Lists!$A$14="","",N(INDEX(Database!$Y:$Y,MATCH(MAXIFS(Database!$A:$A,Database!$B:$B,Lists!$A$14),Database!$A:$A,0)))+N(INDEX(Database!$AC:$AC,MATCH(MAXIFS(Database!$A:$A,Database!$B:$B,Lists!$A$14),Database!$A:$A,0)))+N(INDEX(Database!$AG:$AG,MATCH(MAXIFS(Database!$A:$A,Database!$B:$B,Lists!$A$14),Database!$A:$A,0)))+N(INDEX(Database!$AK:$AK,MATCH(MAXIFS(Database!$A:$A,Database!$B:$B,Lists!$A$14),Database!$A:$A,0)))),"") | D16: =IFERROR(IF(Lists!$A$14="","",INDEX(Database!$L:$L,MATCH(MAXIFS(Database!$A:$A,Database!$B:$B,Lists!$A$14),Database!$A:$A,0))),"") | E16: =IF(Lists!$A$14="","","-") | F16: =IF(Lists!$A$14="","","-") | G16: =IF(Lists!$A$14="","","-") | H16: =IF(Lists!$A$14="","","-") | I16: =IF(Lists!$A$14="","","-") | J16: =IF(Lists!$A$14="","","-")
A17: =IF(Lists!$A$15="","",Lists!$A$15) | B17: =IFERROR(IF(Lists!$A$15="","",INDEX(Database!$G:$G,MATCH(MAXIFS(Database!$A:$A,Database!$B:$B,Lists!$A$15),Database!$A:$A,0))),"") | C17: =IFERROR(IF(Lists!$A$15="","",N(INDEX(Database!$Y:$Y,MATCH(MAXIFS(Database!$A:$A,Database!$B:$B,Lists!$A$15),Database!$A:$A,0)))+N(INDEX(Database!$AC:$AC,MATCH(MAXIFS(Database!$A:$A,Database!$B:$B,Lists!$A$15),Database!$A:$A,0)))+N(INDEX(Database!$AG:$AG,MATCH(MAXIFS(Database!$A:$A,Database!$B:$B,Lists!$A$15),Database!$A:$A,0)))+N(INDEX(Database!$AK:$AK,MATCH(MAXIFS(Database!$A:$A,Database!$B:$B,Lists!$A$15),Database!$A:$A,0)))),"") | D17: =IFERROR(IF(Lists!$A$15="","",INDEX(Database!$L:$L,MATCH(MAXIFS(Database!$A:$A,Database!$B:$B,Lists!$A$15),Database!$A:$A,0))),"") | E17: =IF(Lists!$A$15="","","-") | F17: =IF(Lists!$A$15="","","-") | G17: =IF(Lists!$A$15="","","-") | H17: =IF(Lists!$A$15="","","-") | I17: =IF(Lists!$A$15="","","-") | J17: =IF(Lists!$A$15="","","-")
A18: =IF(Lists!$A$16="","",Lists!$A$16) | B18: =IFERROR(IF(Lists!$A$16="","",INDEX(Database!$G:$G,MATCH(MAXIFS(Database!$A:$A,Database!$B:$B,Lists!$A$16),Database!$A:$A,0))),"") | C18: =IFERROR(IF(Lists!$A$16="","",N(INDEX(Database!$Y:$Y,MATCH(MAXIFS(Database!$A:$A,Database!$B:$B,Lists!$A$16),Database!$A:$A,0)))+N(INDEX(Database!$AC:$AC,MATCH(MAXIFS(Database!$A:$A,Database!$B:$B,Lists!$A$16),Database!$A:$A,0)))+N(INDEX(Database!$AG:$AG,MATCH(MAXIFS(Database!$A:$A,Database!$B:$B,Lists!$A$16),Database!$A:$A,0)))+N(INDEX(Database!$AK:$AK,MATCH(MAXIFS(Database!$A:$A,Database!$B:$B,Lists!$A$16),Database!$A:$A,0)))),"") | D18: =IFERROR(IF(Lists!$A$16="","",INDEX(Database!$L:$L,MATCH(MAXIFS(Database!$A:$A,Database!$B:$B,Lists!$A$16),Database!$A:$A,0))),"") | E18: =IF(Lists!$A$16="","","-") | F18: =IF(Lists!$A$16="","","-") | G18: =IF(Lists!$A$16="","","-") | H18: =IF(Lists!$A$16="","","-") | I18: =IF(Lists!$A$16="","","-") | J18: =IF(Lists!$A$16="","","-")
A19: =IF(Lists!$A$17="","",Lists!$A$17) | B19: =IFERROR(IF(Lists!$A$17="","",INDEX(Database!$G:$G,MATCH(MAXIFS(Database!$A:$A,Database!$B:$B,Lists!$A$17),Database!$A:$A,0))),"") | C19: =IFERROR(IF(Lists!$A$17="","",N(INDEX(Database!$Y:$Y,MATCH(MAXIFS(Database!$A:$A,Database!$B:$B,Lists!$A$17),Database!$A:$A,0)))+N(INDEX(Database!$AC:$AC,MATCH(MAXIFS(Database!$A:$A,Database!$B:$B,Lists!$A$17),Database!$A:$A,0)))+N(INDEX(Database!$AG:$AG,MATCH(MAXIFS(Database!$A:$A,Database!$B:$B,Lists!$A$17),Database!$A:$A,0)))+N(INDEX(Database!$AK:$AK,MATCH(MAXIFS(Database!$A:$A,Database!$B:$B,Lists!$A$17),Database!$A:$A,0)))),"") | D19: =IFERROR(IF(Lists!$A$17="","",INDEX(Database!$L:$L,MATCH(MAXIFS(Database!$A:$A,Database!$B:$B,Lists!$A$17),Database!$A:$A,0))),"") | E19: =IF(Lists!$A$17="","","-") | F19: =IF(Lists!$A$17="","","-") | G19: =IF(Lists!$A$17="","","-") | H19: =IF(Lists!$A$17="","","-") | I19: =IF(Lists!$A$17="","","-") | J19: =IF(Lists!$A$17="","","-")
A20: =IF(Lists!$A$18="","",Lists!$A$18) | B20: =IFERROR(IF(Lists!$A$18="","",INDEX(Database!$G:$G,MATCH(MAXIFS(Database!$A:$A,Database!$B:$B,Lists!$A$18),Database!$A:$A,0))),"") | C20: =IFERROR(IF(Lists!$A$18="","",N(INDEX(Database!$Y:$Y,MATCH(MAXIFS(Database!$A:$A,Database!$B:$B,Lists!$A$18),Database!$A:$A,0)))+N(INDEX(Database!$AC:$AC,MATCH(MAXIFS(Database!$A:$A,Database!$B:$B,Lists!$A$18),Database!$A:$A,0)))+N(INDEX(Database!$AG:$AG,MATCH(MAXIFS(Database!$A:$A,Database!$B:$B,Lists!$A$18),Database!$A:$A,0)))+N(INDEX(Database!$AK:$AK,MATCH(MAXIFS(Database!$A:$A,Database!$B:$B,Lists!$A$18),Database!$A:$A,0)))),"") | D20: =IFERROR(IF(Lists!$A$18="","",INDEX(Database!$L:$L,MATCH(MAXIFS(Database!$A:$A,Database!$B:$B,Lists!$A$18),Database!$A:$A,0))),"") | E20: =IF(Lists!$A$18="","","-") | F20: =IF(Lists!$A$18="","","-") | G20: =IF(Lists!$A$18="","","-") | H20: =IF(Lists!$A$18="","","-") | I20: =IF(Lists!$A$18="","","-") | J20: =IF(Lists!$A$18="","","-")
A21: =IF(Lists!$A$19="","",Lists!$A$19) | B21: =IFERROR(IF(Lists!$A$19="","",INDEX(Database!$G:$G,MATCH(MAXIFS(Database!$A:$A,Database!$B:$B,Lists!$A$19),Database!$A:$A,0))),"") | C21: =IFERROR(IF(Lists!$A$19="","",N(INDEX(Database!$Y:$Y,MATCH(MAXIFS(Database!$A:$A,Database!$B:$B,Lists!$A$19),Database!$A:$A,0)))+N(INDEX(Database!$AC:$AC,MATCH(MAXIFS(Database!$A:$A,Database!$B:$B,Lists!$A$19),Database!$A:$A,0)))+N(INDEX(Database!$AG:$AG,MATCH(MAXIFS(Database!$A:$A,Database!$B:$B,Lists!$A$19),Database!$A:$A,0)))+N(INDEX(Database!$AK:$AK,MATCH(MAXIFS(Database!$A:$A,Database!$B:$B,Lists!$A$19),Database!$A:$A,0)))),"") | D21: =IFERROR(IF(Lists!$A$19="","",INDEX(Database!$L:$L,MATCH(MAXIFS(Database!$A:$A,Database!$B:$B,Lists!$A$19),Database!$A:$A,0))),"") | E21: =IF(Lists!$A$19="","","-") | F21: =IF(Lists!$A$19="","","-") | G21: =IF(Lists!$A$19="","","-") | H21: =IF(Lists!$A$19="","","-") | I21: =IF(Lists!$A$19="","","-") | J21: =IF(Lists!$A$19="","","-")
A22: =IF(Lists!$A$20="","",Lists!$A$20) | B22: =IFERROR(IF(Lists!$A$20="","",INDEX(Database!$G:$G,MATCH(MAXIFS(Database!$A:$A,Database!$B:$B,Lists!$A$20),Database!$A:$A,0))),"") | C22: =IFERROR(IF(Lists!$A$20="","",N(INDEX(Database!$Y:$Y,MATCH(MAXIFS(Database!$A:$A,Database!$B:$B,Lists!$A$20),Database!$A:$A,0)))+N(INDEX(Database!$AC:$AC,MATCH(MAXIFS(Database!$A:$A,Database!$B:$B,Lists!$A$20),Database!$A:$A,0)))+N(INDEX(Database!$AG:$AG,MATCH(MAXIFS(Database!$A:$A,Database!$B:$B,Lists!$A$20),Database!$A:$A,0)))+N(INDEX(Database!$AK:$AK,MATCH(MAXIFS(Database!$A:$A,Database!$B:$B,Lists!$A$20),Database!$A:$A,0)))),"") | D22: =IFERROR(IF(Lists!$A$20="","",INDEX(Database!$L:$L,MATCH(MAXIFS(Database!$A:$A,Database!$B:$B,Lists!$A$20),Database!$A:$A,0))),"") | E22: =IF(Lists!$A$20="","","-") | F22: =IF(Lists!$A$20="","","-") | G22: =IF(Lists!$A$20="","","-") | H22: =IF(Lists!$A$20="","","-") | I22: =IF(Lists!$A$20="","","-") | J22: =IF(Lists!$A$20="","","-")
A23: =IF(Lists!$A$21="","",Lists!$A$21) | B23: =IFERROR(IF(Lists!$A$21="","",INDEX(Database!$G:$G,MATCH(MAXIFS(Database!$A:$A,Database!$B:$B,Lists!$A$21),Database!$A:$A,0))),"") | C23: =IFERROR(IF(Lists!$A$21="","",N(INDEX(Database!$Y:$Y,MATCH(MAXIFS(Database!$A:$A,Database!$B:$B,Lists!$A$21),Database!$A:$A,0)))+N(INDEX(Database!$AC:$AC,MATCH(MAXIFS(Database!$A:$A,Database!$B:$B,Lists!$A$21),Database!$A:$A,0)))+N(INDEX(Database!$AG:$AG,MATCH(MAXIFS(Database!$A:$A,Database!$B:$B,Lists!$A$21),Database!$A:$A,0)))+N(INDEX(Database!$AK:$AK,MATCH(MAXIFS(Database!$A:$A,Database!$B:$B,Lists!$A$21),Database!$A:$A,0)))),"") | D23: =IFERROR(IF(Lists!$A$21="","",INDEX(Database!$L:$L,MATCH(MAXIFS(Database!$A:$A,Database!$B:$B,Lists!$A$21),Database!$A:$A,0))),"") | E23: =IF(Lists!$A$21="","","-") | F23: =IF(Lists!$A$21="","","-") | G23: =IF(Lists!$A$21="","","-") | H23: =IF(Lists!$A$21="","","-") | I23: =IF(Lists!$A$21="","","-") | J23: =IF(Lists!$A$21="","","-")
A24: PORTFOLIO TOTAL | C24: =SUM(C4:C23) | D24: =SUM(D4:D23)
A26: Note: EGR/NOI/cost $ roll-ups recompute from each project's stored inputs (DB holds raw assumptions); wired fully alongside the calc engine next pass.

Sheet Project Dashboard
A1: PROJECT DASHBOARD - read-only single-project view (printable)
A3: Project | B3: RAD 1
A5: Renders the operating proforma for the selected project from the database latest record. (Full recompute wired with the calc engine next pass.)
A7: Operating Proforma | B7: $ Annual
A8: Gross Potential Rent | B8: ="-"
A9: Effective Rental Revenue | B9: ="-"
A10: Other Income | B10: ="-"
A11: Effective Gross Revenue (EGR) | B11: ="-"
A12: Total Operating Expenses | B12: ="-"
A13: Net Operating Income | B13: ="-"
A14: OpEx Ratio | B14: ="-"

Sheet Monthly CF
A1: MONTHLY CF - FUTURE calc engine placeholder (date spine only this pass)
A2: Spine driven by the Console closing date for the selected project. Operating CFs / capital costs / unlevered CFs plug in below later.
A4: Closing date (from Console) | B4: =Closing_Date_Cell
A6: Month index | C6: 1 | D6: 2 | E6: 3 | F6: 4 | G6: 5 | H6: 6 | I6: 7 | J6: 8 | K6: 9 | L6: 10 | M6: 11 | N6: 12 | O6: 13 | P6: 14 | Q6: 15 | R6: 16 | S6: 17 | T6: 18 | U6: 19 | V6: 20 | W6: 21 | X6: 22 | Y6: 23 | Z6: 24 | AA6: 25 | AB6: 26 | AC6: 27 | AD6: 28 | AE6: 29 | AF6: 30 | AG6: 31 | AH6: 32 | AI6: 33 | AJ6: 34 | AK6: 35 | AL6: 36 | AM6: 37 | AN6: 38 | AO6: 39 | AP6: 40 | AQ6: 41 | AR6: 42 | AS6: 43 | AT6: 44 | AU6: 45 | AV6: 46 | AW6: 47 | AX6: 48 | AY6: 49 | AZ6: 50 | BA6: 51 | BB6: 52 | BC6: 53 | BD6: 54 | BE6: 55 | BF6: 56 | BG6: 57 | BH6: 58 | BI6: 59 | BJ6: 60 | BK6: 61 | BL6: 62 | BM6: 63 | BN6: 64 | BO6: 65 | BP6: 66 | BQ6: 67 | BR6: 68 | BS6: 69 | BT6: 70 | BU6: 71 | BV6: 72 | BW6: 73 | BX6: 74 | BY6: 75 | BZ6: 76 | CA6: 77 | CB6: 78 | CC6: 79 | CD6: 80 | CE6: 81 | CF6: 82 | CG6: 83 | CH6: 84 | CI6: 85 | CJ6: 86 | CK6: 87 | CL6: 88 | CM6: 89 | CN6: 90 | CO6: 91 | CP6: 92 | CQ6: 93 | CR6: 94 | CS6: 95 | CT6: 96 | CU6: 97 | CV6: 98 | CW6: 99 | CX6: 100 | CY6: 101 | CZ6: 102 | DA6: 103 | DB6: 104 | DC6: 105 | DD6: 106 | DE6: 107 | DF6: 108 | DG6: 109 | DH6: 110 | DI6: 111 | DJ6: 112 | DK6: 113 | DL6: 114 | DM6: 115 | DN6: 116 | DO6: 117 | DP6: 118 | DQ6: 119 | DR6: 120
A7: Month start | C7: =EDATE($B$4,0) | D7: =EDATE($B$4,1) | E7: =EDATE($B$4,2) | F7: =EDATE($B$4,3) | G7: =EDATE($B$4,4) | H7: =EDATE($B$4,5) | I7: =EDATE($B$4,6) | J7: =EDATE($B$4,7) | K7: =EDATE($B$4,8) | L7: =EDATE($B$4,9) | M7: =EDATE($B$4,10) | N7: =EDATE($B$4,11) | O7: =EDATE($B$4,12) | P7: =EDATE($B$4,13) | Q7: =EDATE($B$4,14) | R7: =EDATE($B$4,15) | S7: =EDATE($B$4,16) | T7: =EDATE($B$4,17) | U7: =EDATE($B$4,18) | V7: =EDATE($B$4,19) | W7: =EDATE($B$4,20) | X7: =EDATE($B$4,21) | Y7: =EDATE($B$4,22) | Z7: =EDATE($B$4,23) | AA7: =EDATE($B$4,24) | AB7: =EDATE($B$4,25) | AC7: =EDATE($B$4,26) | AD7: =EDATE($B$4,27) | AE7: =EDATE($B$4,28) | AF7: =EDATE($B$4,29) | AG7: =EDATE($B$4,30) | AH7: =EDATE($B$4,31) | AI7: =EDATE($B$4,32) | AJ7: =EDATE($B$4,33) | AK7: =EDATE($B$4,34) | AL7: =EDATE($B$4,35) | AM7: =EDATE($B$4,36) | AN7: =EDATE($B$4,37) | AO7: =EDATE($B$4,38) | AP7: =EDATE($B$4,39) | AQ7: =EDATE($B$4,40) | AR7: =EDATE($B$4,41) | AS7: =EDATE($B$4,42) | AT7: =EDATE($B$4,43) | AU7: =EDATE($B$4,44) | AV7: =EDATE($B$4,45) | AW7: =EDATE($B$4,46) | AX7: =EDATE($B$4,47) | AY7: =EDATE($B$4,48) | AZ7: =EDATE($B$4,49) | BA7: =EDATE($B$4,50) | BB7: =EDATE($B$4,51) | BC7: =EDATE($B$4,52) | BD7: =EDATE($B$4,53) | BE7: =EDATE($B$4,54) | BF7: =EDATE($B$4,55) | BG7: =EDATE($B$4,56) | BH7: =EDATE($B$4,57) | BI7: =EDATE($B$4,58) | BJ7: =EDATE($B$4,59) | BK7: =EDATE($B$4,60) | BL7: =EDATE($B$4,61) | BM7: =EDATE($B$4,62) | BN7: =EDATE($B$4,63) | BO7: =EDATE($B$4,64) | BP7: =EDATE($B$4,65) | BQ7: =EDATE($B$4,66) | BR7: =EDATE($B$4,67) | BS7: =EDATE($B$4,68) | BT7: =EDATE($B$4,69) | BU7: =EDATE($B$4,70) | BV7: =EDATE($B$4,71) | BW7: =EDATE($B$4,72) | BX7: =EDATE($B$4,73) | BY7: =EDATE($B$4,74) | BZ7: =EDATE($B$4,75) | CA7: =EDATE($B$4,76) | CB7: =EDATE($B$4,77) | CC7: =EDATE($B$4,78) | CD7: =EDATE($B$4,79) | CE7: =EDATE($B$4,80) | CF7: =EDATE($B$4,81) | CG7: =EDATE($B$4,82) | CH7: =EDATE($B$4,83) | CI7: =EDATE($B$4,84) | CJ7: =EDATE($B$4,85) | CK7: =EDATE($B$4,86) | CL7: =EDATE($B$4,87) | CM7: =EDATE($B$4,88) | CN7: =EDATE($B$4,89) | CO7: =EDATE($B$4,90) | CP7: =EDATE($B$4,91) | CQ7: =EDATE($B$4,92) | CR7: =EDATE($B$4,93) | CS7: =EDATE($B$4,94) | CT7: =EDATE($B$4,95) | CU7: =EDATE($B$4,96) | CV7: =EDATE($B$4,97) | CW7: =EDATE($B$4,98) | CX7: =EDATE($B$4,99) | CY7: =EDATE($B$4,100) | CZ7: =EDATE($B$4,101) | DA7: =EDATE($B$4,102) | DB7: =EDATE($B$4,103) | DC7: =EDATE($B$4,104) | DD7: =EDATE($B$4,105) | DE7: =EDATE($B$4,106) | DF7: =EDATE($B$4,107) | DG7: =EDATE($B$4,108) | DH7: =EDATE($B$4,109) | DI7: =EDATE($B$4,110) | DJ7: =EDATE($B$4,111) | DK7: =EDATE($B$4,112) | DL7: =EDATE($B$4,113) | DM7: =EDATE($B$4,114) | DN7: =EDATE($B$4,115) | DO7: =EDATE($B$4,116) | DP7: =EDATE($B$4,117) | DQ7: =EDATE($B$4,118) | DR7: =EDATE($B$4,119)

Sheet Lists
A1: Project | B1: Status | C1: UnitType | D1: RentBasis | E1: YesNo | F1: RentType | G1: CostCurve
A2: RAD 1 | B2: Current | C2: Studio | D2: Market | E2: Yes | F2: NNN | G2: S-curve
A3: RAD 2 | B3: Historical | C3: 1 Bedroom | D3: Live Local | E3: No | F3: Gross | G3: Straight
A4: Live Local A | C4: 2 Bedroom | D4: LIHTC | G4: Front-loaded
C5: 3 Bedroom | D5: PBV | G5: Back-loaded
D6: RAD

Sheet Archive
A1: ARCHIVE - purged records (FIFO overflow). Recoverable, not hard-deleted.
A3: RecordID | B3: Project | C3: Status | D3: Timestamp | E3: UpdatedBy | F3: Notes | G3: PhaseNo | H3: ProjectName | I3: LandAcres | J3: ClosingDate | K3: GSF | L3: NSF | M3: off_ConstStart | N3: off_InitOcc | O3: off_ConstEnd | P3: off_Stab | Q3: HasCommercial | R3: CommSF | S3: CommRentPSF | T3: CommEscalation | U3: CommAbatement | V3: CommVacancy | W3: CommOpExPSF | X3: UM1_Type | Y3: UM1_Count | Z3: UM1_AvgSF | AA3: UM1_PUPM | AB3: UM2_Type | AC3: UM2_Count | AD3: UM2_AvgSF | AE3: UM2_PUPM | AF3: UM3_Type | AG3: UM3_Count | AH3: UM3_AvgSF | AI3: UM3_PUPM | AJ3: UM4_Type | AK3: UM4_Count | AL3: UM4_AvgSF | AM3: UM4_PUPM | AN3: ResVacancy | AO3: ResConcessions | AP3: ResModel | AQ3: ResCollLoss | AR3: OI1_Name | AS3: OI1_PUPM | AT3: OI2_Name | AU3: OI2_PUPM | AV3: OI3_Name | AW3: OI3_PUPM | AX3: OI4_Name | AY3: OI4_PUPM | AZ3: OI5_Name | BA3: OI5_PUPM | BB3: OpEx_Payroll | BC3: OpEx_Marketing | BD3: OpEx_Admin | BE3: OpEx_ProfFees | BF3: OpEx_RM | BG3: OpEx_Utilities | BH3: OpEx_Insurance | BI3: OpEx_RETaxes | BJ3: OpEx_MgmtFeePct | BK3: Bud_Land | BL3: Bud_Shell | BM3: Bud_Sitework | BN3: Bud_Parking | BO3: Bud_FFE | BP3: Bud_GCFee | BQ3: Bud_AE | BR3: Bud_Permits | BS3: Bud_Legal | BT3: Bud_Mktg | BU3: Bud_DevFee | BV3: Bud_TaxIns
